Workbook

Sheet Budget
A1: to | B1: trip | C1: date - | D1: destination | E1: ticket | F1: visa | G1: currency commission | H1: acc | I1: misc | J1: transport inc airport | K1: food | L1: extra kg | M1: cargo | N1: airport duty | O1: stock | P1: personal | Q1: 2 MONTHS RENTAL | R1: 2 MONTHS SALARIES | S1: TOTAL COST | T1: TOTAL overheads | U1: total recommende sales value | V1: total actual sales value | W1: profit | X1: profit in USD
B3: istanbul | C3: 30 may-10 june 2021 | D3: istanbul | E3: 930 | F3: 230 | H3: 200 | J3: 10 | K3: 50 | M3: =886+1723+1000 -> 3609 | O3: 9148 | P3: 500 | Q3: 400 | R3: 400 | S3: =SUM(E3:R3) -> 15477
B7: istanbul november 2021 trip
B8: 0 | G8: =844*0.04+75 -> 108.76 | H8: =25*6 -> 150 | I8: =3*15+10 -> 55 | J8: 50 | K8: 20 | L8: 250 | M8: 1200 | N8: 360 | O8: 6556 | P8: 0 | Q8: 400 | R8: 600 | S8: =SUM(B8:R8) -> 9749.76
B10: istanbul kapura Dec | I10: =+O10*0.06 -> 210.3 | M10: =70*17+50+20*17+50 -> 1630 | O10: =1992+1048+465 -> 3505 | Q10: 200 | R10: 700 | S10: =SUM(G10:R10) -> 6245.3
B13: istanbul april2022 | E13: 850 | H13: =135+60 -> 195 | I13: 55 | J13: 50 | K13: 20 | L13: =4*110+75*3 -> 665 | M13: =80*17.5+50 -> 1450 | N13: =720+15+40 -> 775 | O13: =+'stock purchase 2023'!#REF! -> #REF! | P13: =100+15+35+20+17+18+15+10+35 -> 265 | Q13: 300 | R13: 375 | S13: =SUM(E13:R13) -> #REF!
B16: istanbulsept 2022 | C16: 10 -22 sept | D16: istanbul | E16: =1220+135 -> 1355 | F16: 220 | G16: =3000*0.05 -> 150 | H16: =40+30*5+80 -> 270 | I16: 50 | J16: 50 | K16: 50 | L16: =3*120+4*75 -> 660 | M16: 0 | N16: =600+30+40 -> 670 | O16: 6911 | P16: =66+10+200+40+50 -> 366 | Q16: 500 | R16: 375 | S16: =SUM(E16:R16) -> 11627 | T16: =+E16+F16+G16+H16+I16+J16+K16+L16+M16+N16+P16+Q16+R16 -> 4716
B17: via Germany | C17: 17-20 sept | D17: germany | E17: 370
B19: ISTANBUL | C19: 19-27 NOV | D19: ISTANBUL | E19: 800 | H19: 250 | I19: 16 | J19: 50 | K19: 50 | L19: 200 | N19: 480 | O19: 4607 | P19: 250 | Q19: 500 | R19: 400 | S19: =SUM(E19:R19) -> 7603 | T19: =+S19-O19 -> 2996 | U19: =+'stock purchase 2023'!#REF! -> #REF! | V19: =+'stock purchase 2023'!#REF! -> #REF! | W19: =+V19-S19 -> #REF!
B23: istanbul March 2023 | C23: 5-12 mar | D23: istanbul | E23: 1235 | H23: 240 | I23: 100 | J23: 50 | K23: 50 | L23: =500+225 -> 725 | N23: 840 | O23: 8267 | P23: 50 | Q23: =+(2200+500) -> 2700 | R23: 1000 | S23: =SUM(E23:R23) -> 15257 | T23: =+S23-O23 -> 6990
B24: via Germany | C24: 28 feb-4 march | D24: germany | E24: 100 | H24: 180 | I24: 50 | J24: 40 | K24: 40 | S24: =SUM(E24:R24) -> 410 | T24: =+S24 -> 410
T25: =SUM(T23:T24) -> 7400
B26: istanbul | C26: 7-13 march | D26: istanbul | E26: 951 | H26: 240 | I26: 100 | J26: =50+30 -> 80 | K26: =50+20 -> 70 | L26: =500+75*9 -> 1175 | N26: =8*120+90 -> 1050 | O26: 9682 | P26: 400 | Q26: =2200+500 -> 2700 | R26: =+(400+400+200) -> 1000 | S26: =SUM(E26:R26) -> 17448 | T26: =+S26-O26 -> 7766
L28: =+E26+H26+I26+J26+K26+L26+N26 -> 3666 | M28: =+L26+N26 -> 2225 | N28: =32*8 -> 256
L29: =+L28/N28 -> 14.320312 | N29: =+M28/N28 -> 8.6914062
B30: ISTANBUL MAY 2023
B34: ISTANBUL | C34: 2-9 JULY 2023 | D34: istanbul | E34: 1080 | H34: 200 | I34: 50 | J34: =40+40+5+7 -> 92 | K34: 20 | L34: =130+300 -> 430 | M34: =15*16.5+25 -> 272.5 | N34: 480 | O34: 6066 | P34: 200 | Q34: =950*2+250*2 -> 2400 | R34: =+(175*2+100*2)+240 -> 790 | S34: =SUM(E34:R34) -> 12080.5 | T34: =+S34-O34 -> 6014.5
B37: istanbul sept/oct | C37: 25-29 15-18 | D37: istanbul | E37: 930 | F37: 400 | H37: =8*45 -> 360 | I37: =60+100+35+35 -> 230 | J37: =50+30+40+10 -> 130 | K37: 50 | L37: =2*120+3*75 -> 465 | M37: =502+25*16.5+25*16.5 -> 1327 | N37: =4*120 -> 480 | O37: 6440 | P37: 100 | Q37: =950*2+250*2 -> 2400 | R37: =+(175*2+120*2)+240 -> 830 | S37: =SUM(E37:R37) -> 14142 | T37: =+S37-O37 -> 7702
B38: new york | C38: 30-14 oct | D38: new york/ florida | E38: 900 | F38: 160 | H38: =593+180 -> 773 | J38: =42+42+27+60+17+14+8 -> 210 | K38: 180 | L38: =30+40 -> 70 | N38: 120 | O38: 1327 | P38: =54+25+35+29+20+53 -> 216 | S38: =SUM(E38:R38) -> 3956 | T38: =+S38-O38 -> 2629
B39: total | E39: =SUM(E37:E38) -> 1830 | F39: =SUM(F37:F38) -> 560 | G39: =SUM(G37:G38) -> 0 | H39: =SUM(H37:H38) -> 1133 | I39: =SUM(I37:I38) -> 230 | J39: =SUM(J37:J38) -> 340 | K39: =SUM(K37:K38) -> 230 | L39: =SUM(L37:L38) -> 535 | ... P39: =SUM(P37:P38) -> 316 | S39: =SUM(S37:S38) -> 18098 | T39: =SUM(T37:T38) -> 10331
B41: BABY WEAR | C41: 25-29 15-18 | D41: istanbul | E41: 300 | F41: 50 | G41: 0 | H41: 0 | I41: 100 | J41: 20 | K41: 20 | L41: 200 | M41: 439 | N41: 120 | O41: 2400 | Q41: 500 | R41: 300 | S41: =SUM(E41:R41) -> 4449 | T41: =+S41-O41 -> 2049
B44: istanbul | C44: 13-20nov | D44: istanbul | E44: 800 | H44: =6*45 -> 270 | I44: 50 | J44: 30 | K44: 50 | M44: 902 | O44: 3687 | P44: 30 | Q44: 500 | R44: =350+240+360 -> 950 | S44: =SUM(E44:R44) -> 7269 | T44: =+S44-O44 -> 3582
B45: BABY WEAR | E45: 300 | H45: =2*35 -> 70 | I45: 150 | K45: 20 | M45: =568-8*15.5+600 -> 1044 | O45: 1215 | P45: 20 | Q45: 500 | R45: 420 | S45: =SUM(E45:R45) -> 3739 | T45: =+S45-O45 -> 2524
B47: baby wear omer | C47: cargo | M47: 400 | O47: 532 | Q47: 500 | R47: 400 | S47: =SUM(E47:R47) -> 1832 | T47: =+S47-O47 -> 1300
B83: NOTES
B84: MARCH TRIP - | C84: FIND MANY CLEARANCE SALES, good opportunity for big margins
C85: buy outfits & dresses for occassions then
C86: buy winter items and leave for may, can also do kapura
C87: if i buy winter things on layby i should not do a trip in June coz this coincides with layby final payments, cargo costs and duty.
C88: unless the trip is for going to collect the items on layby
C89: JACKETS ARE NOT PROFITABLE IF BOUGHT FOR MORE THAN $15 EACH
C90: winter items are bulky and heavy. Resulting in high cargo charges. Better to buy winter items all through out the year.
E93: jan-dec 208m
E105: SALES ANALYSIS 2016-2021
E106: month | F106: 2016 | G106: 2017 | H106: 2018 | I106: 2019 | J106: 2020 | K106: 2021
E107: jan | F107: 3811 | I107: 2814 | J107: 4180
E108: feb | F108: 4126 | I108: 2883 | J108: 3413
E109: mar | F109: 5742 | I109: 6262 | J109: 6532
E110: apr | F110: 12651 | I110: 2162 | J110: 128
E111: may | F111: 5651 | I111: 6517 | J111: 3594
...

Sheet STOCK TAKE
A1: to
B2: STOCK TAKE OCTOBER 2020
B4: LABEL | C4: DESCRIPTION | D4: PURCHASE PRICE | E4: SALE PRICE | J4: LABEL | K4: DESCRIPTION | L4: PURCHASE PRICE | M4: SALE PRICE
B6: MISSING STOCK | J6: MISSING STOCK
A7: 1 | B7: Le mirage | C7: burnt orage/white 2 piece | D7: 25 | I7: 1 | J7: adalyn | K7: navy dress w pleated back
A8: 2 | B8: le mirage | C8: navy 2 pc w printed skirt | D8: 25 | J8: versace | K8: grey 2 piece track suit from avondale
A9: 3 | B9: ell shirt dress | C9: shirt dress | D9: 9 | J9: nesly | K9: coffee suit
B10: tights | C10: tights | D10: 5 | K10: nesly coffee suit
B11: oreya | C11: maroon sude wedge shoe | D11: 8 | J11: TANGO EZGI | K11: PINK TOP/FLOWERY SKIRT
D12: =SUM(D7:D11) -> 72
B13: eastgate sales
A14: 1 | B14: yuxi fashion | C14: red wrap over dress | D14: 10 | E14: 45
C15: green dress cotton multi colour
B17: SALES ANALYSIS BY CATGORY
B18: STOCK | C18: OPENING QNTY | D18: CLOSING QNTY | E18: SALES QNTY | F18: % SALE | K18: stock not on stock sheet
B19: DRESS OUTFITS | J19: 1 | K19: mardi | L19: green/beige floral flared dress repeat - | M19: 28 | N19: 110
B20: 2 PIECE OUTFITS
B21: DRESSES | C21: 669 | D21: 355 | E21: =+C21-D21 -> 314 | F21: =+E21/C21*100 -> 46.935725 | K21: oreya white t shirt w front glitter
B22: SKIRTS | C22: 106 | D22: 83 | E22: =+C22-D22 -> 23 | F22: =+E22/C22*100 -> 21.698113 | K22: FI & BI | L22: black jeggin 46 | M22: sold but not on stocksheet
B23: TOPS | C23: 155 | D23: 86 | E23: =+C23-D23 -> 69 | F23: =+E23/C23*100 -> 44.516129
B24: TROUSERS | C24: 59 | D24: 34 | E24: =+C24-D24 -> 25 | F24: =+E24/C24*100 -> 42.372881
B25: WOOLEN TOPS | C25: 99 | D25: 41 | E25: =+C25-D25 -> 58 | F25: =+E25/C25*100 -> 58.585859
B26: JACKETS | C26: 31 | D26: 22 | E26: =+C26-D26 -> 9 | F26: =+E26/C26*100 -> 29.032258
B27: JERSEY | C27: 59 | D27: 26 | E27: =+C27-D27 -> 33 | F27: =+E27/C27*100 -> 55.932203
B28: TRACK SUITS | C28: 59 | D28: 34 | E28: =+C28-D28 -> 25 | F28: =+E28/C28*100 -> 42.372881
B29: SHOES | C29: 200 | D29: 111 | E29: =+C29-D29 -> 89 | F29: =+E29/C29*100 -> 44.5
B30: CLUTCH | C30: 12 | D30: 6 | E30: =+C30-D30 -> 6 | F30: =+E30/C30*100 -> 50
B31: COSERT | C31: 10 | D31: 4 | E31: =+C31-D31 -> 6 | F31: =+E31/C31*100 -> 60
B32: HANDBAGS | C32: 25 | D32: 9 | E32: =+C32-D32 -> 16 | F32: =+E32/C32*100 -> 64
B33: PANTY | C33: 103 | D33: 49 | E33: =+C33-D33 -> 54 | F33: =+E33/C33*100 -> 52.427184
B34: GYPSY SOCKS | C34: 40 | D34: 36 | E34: =+C34-D34 -> 4 | F34: =+E34/C34*100 -> 10
B45: OCTOBER STOCK TAKE 2022
C46: over | D46: under
B47: OVERS
B48: rouge grey knit dress 2 pc w hood
B50: UNDER
A51: channel | B51: navy | E51: balance with the one addedback jan 2022 stock take
B52: SKIRTS
A53: escarell | B53: black knit | E53: To check amount actually bought
A54: escarell | B54: black knit | E54: To check amount actually bought
...

Sheet cashflow
A1: to | B1: CASHFLOW -2018 | C1: Jan | D1: Feb | E1: Mar | F1: Apr | G1: May | H1: Jun | I1: Jul | J1: Aug | K1: Sep | L1: Oct | M1: Nov | N1: Dec | P1: %
B2: INFLOWS
B3: SALES
B4: Cash sales | C4: =+'daily sales'!B139 -> 3230
B5: pos purchases
C6: =SUM(C4:C5) -> 3230
B8: LOANS
B9: stanbic bank loan
B10: loans personal
B11: loans other
B14: refunds
B17: Total | C17: =+C6+C12+C14 -> 3230
B19: MONTHLY EXPENSES
B20: stock purchases | C20: =+cashbook!#REF!+cashbook!#REF!+cashbook!#REF!+cashbook!#REF!+cashbook!#REF! -> #REF! | S20: 145
B22: operating expenses | C22: =SUM(C23:C58) -> 1903 | S22: 255
B23: parking | C23: 10 | S23: 75
B24: fuel | C24: 20 | S24: 50
B25: salaries
B26: Pauline | S26: 155
B27: Tatenda | S27: 323
B28: allowance self | C28: 321 | S28: 195
B29: staff transport allowance | S29: 62
B30: Pauline | C30: =87+18 -> 105
B31: Tatenda
B32: staff commission
B33: Pauline | C33: 21
B34: Tatenda | C34: 21
B35: rentals | C35: 250 | S35: 30
B36: rates | S36: =SUM(S20:S35) -> 1290
B37: electricity
B38: cleaning & packaging materials & shop utilities | C38: 10
B39: stationery
B40: car running expenses | R40: =346-24-13 -> 309
B41: miscellaneous
B42: airtime | C42: 50
B43: Business refreshments
B44: small asset procurement
B45: big asset procurement | C45: 600
B46: sales discount
B47: refunds
...

Sheet cashbook
A1: to | C1: cash USD | D1: debit card | E1: Cash bond ecocash | F1: cash /DEBIT convert to USD | G1: TOTAL | J1: expenditure | K1: cash | L1: personal
I2: 45292 | J2: 1K ROUND | K2: 1000
I3: week 1-2 | J3: FSBS club round | K3: 300
J4: teamwork | K4: 300
J5: sharewealth | K5: 1000
J6: shop licence | K6: =3865400/10800 -> 357.90741
J7: transport x2 weeks | K7: =15+15+12 -> 42
J8: personal round table | L8: 70
J9: simukai support jan | K9: 75
I10: week 3 | J10: transport tatenda | K10: 18
I11: 15-20 jan | J11: fire extinguisher service | K11: 20
J12: shop supplies | K12: 5
J13: personal, | L13: =240000/11000+10 -> 31.818182
I14: 22-27 jan | J14: transport tatenda | K14: 18
J15: plastic packaging | K15: 20
J16: personal | L16: =20+28+10+20 -> 78
I17: 29-31 jan | J17: transport tatenda | K17: 18
J18: transport Pau | K18: 18
J25: FEBRUARY
I26: week 1 | J26: Salary Tatenda | K26: 175
J27: Salary Pau | K27: 175
J28: transport allowance pau | K28: 15
J29: transport allowance tatenda | K29: 15
I30: week 2 | J30: transport allowance pau | K30: 15
J31: transport allowance tatenda | K31: 15
J32: advertising online casper | K32: 60
J33: 1 k round | K33: 1000
J34: baby shop goodwill | K34: 1000
J35: baby shop original stock | K35: 780
J36: staff december commisions | K36: 110
J37: turkey ticket (kudzai loan) | K37: =731+190 -> 921
J38: shop utilities - plastic packaging | K38: 20
J39: personal fsbs jan subs | L39: 80
J40: round table jan | K40: 70
J41: personal, | L41: =10+30+20 -> 60
I42: week 3 | J42: transport allowance pau | K42: 15
J43: transport allowance tatenda on sick leave) | K43: 6
J44: RENTALS | K44: 230
J45: personal | L45: =14+10 -> 24
I46: week 4 | J46: transport allowance pau | K46: 15
...

Sheet cash budget
A3: =+'daily sales'!#REF!+'daily sales'!#REF! -> #REF! | E3: =1014+2900+594 -> 4508
E5: 900
A6: =SUM(A3:A5) -> #REF! | E6: =SUM(E2:E5) -> 5408
M8: nov
B9: 15
A13: 10
A14: 120 | B14: 80
A15: 375 | B15: 250 | C15: 245 | E15: =150+260 -> 410 | F15: 550
A16: 465 | C16: 465 | E16: 458 | F16: 450
A17: 30 | B17: 15
A22: 20
A23: 55 | C23: 70
A24: 550
A25: 165
A29: =400+40+40 -> 480
A30: 740.6 | F30: 1345
B31: 200 | F31: 200
F33: =30*4 -> 120
F34: 50
F35: 50
F37: 300
F40: 200
E43: 1820
A46: 75
A49: 500 | B49: =500+376 -> 876 | E49: 798 | F49: 249
A50: 263 | C50: 358 | E50: 1525 | F50: 300
A52: 543 | C52: 543 | E52: 543 | F52: 543
A55: 500 | C55: 500 | E55: 225 | F55: 225
A56: 103 | C56: 103 | E56: 103 | F56: 103
C57: 129
A59: =SUM(A9:A58) -> 4994.6 | B59: =SUM(B9:B58) -> 1436 | C59: =SUM(C9:C58) -> 2413 | D59: =SUM(D9:D58) -> 0 | E59: =SUM(E9:E58) -> 5882 | F59: =SUM(F9:F58) -> 4685
A62: =+A6-A59 -> #REF!
A211: week 1 expenditure | B211: Jan week 4 | C211: feb week 1 | D211: feb week 2 | E211: feb week 3 | F211: feb week 4
A212: daily round
A213: 1000 round | C213: 1000
A214: round table
A215: weekly 25 round | C215: 200 | D215: 200 | E215: 200 | F215: 200
A216: fsbs | C216: 300
A217: teamwork | C217: 300
A218: rentals | F218: 250
...

Sheet o stock
A1: SHOP | B1: LABEL | C1: Q | D1: size | E1: Item | F1: purchase price / unit $ | G1: total purchase price | H1: total cost | I1: Indirect Cost / unit | J1: Total Unit Cost | K1: Multiplier | L1: recommended | M1: Actual Price | N1: SALE | O1: S/T DEC '23 | P1: status | Q1: date | R1: sales
A2: DRESS OUTFITS
E3: OUTFITS & SUITS
A4: femeny | B4: jf lefone | C4: 1 | E4: white dress & jacket | F4: 33 | G4: 5920.5 | H4: 13960 | I4: =+F4/G4*H4 -> 77.810996 | J4: =+F4+I4 -> 110.811 | K4: 0.3 | L4: =+J4*K4+J4 -> 144.05429 | M4: 150
B5: dancing queen | C5: 2 | D5: 48 | E5: silver & black 2 piece | F5: 45 | G5: 5920.5 | H5: 13960 | I5: =+F5/G5*H5 -> 106.1059 | J5: =+F5+I5 -> 151.1059 | K5: 0.3 | L5: =+J5*K5+J5 -> 196.43767 | M5: 100 | N5: 80 | P5: nyamakupi | Q5: 45351 | R5: =+N5*15000 -> 1200000
B6: dancing queen | C6: 3 | D6: 48 | E6: silver & black 2 piece | F6: 45 | G6: 5920.5 | H6: 13960 | I6: =+F6/G6*H6 -> 106.1059 | J6: =+F6+I6 -> 151.1059 | K6: 0.3 | L6: =+J6*K6+J6 -> 196.43767 | M6: 100
B7: hatunga | C7: 4 | D7: 38 | E7: gold 2 piece with front glitter | L7: =+J7*K7+J7 -> 0 | P7: from eastgate
B8: fascino | C8: 5 | D8: 44 | E8: fascino cream/gold 2pc | F8: 55 | G8: 5500 | H8: 11950 | I8: =+F8/G8*H8 -> 119.5 | K8: 0.3 | L8: =+J8*K8+J8 -> 0 | M8: 220
B9: mavellino | C9: 6 | D9: 42 | E9: striped blue dress suit | F9: 55 | G9: 5690 | H9: 9443 | I9: =+F9/G9*H9 -> 91.276801 | J9: =+F9+I9 -> 146.2768 | K9: 0.3 | M9: 180
B10: march 2019 stock | L10: =+J10*K10+J10 -> 0
B11: hatunga | C11: 7 | D11: 42 | E11: navy/pink 3 piece | F11: 50 | G11: 4794 | H11: 7939 | I11: =+F11/G11*H11 -> 82.801418 | J11: =+F11+I11 -> 132.80142 | K11: 0.3 | L11: =+J11*K11+J11 -> 172.64184 | M11: 200
B12: hatunga | C12: 8 | D12: 44 | E12: navy/pink 3 piece | F12: 50 | G12: 4794 | H12: 7939 | I12: =+F12/G12*H12 -> 82.801418 | J12: =+F12+I12 -> 132.80142 | K12: 0.3 | L12: =+J12*K12+J12 -> 172.64184 | M12: 200 | P12: cash returned
E13: FEB 2020 STOCK | L13: =+J13*K13+J13 -> 0
A14: NIDA | B14: lavous | C14: 9 | D14: 48 | E14: scotch & yellow 2 piece | F14: 19 | G14: 5690 | H14: 9443 | I14: =+F14/G14*H14 -> 31.531986 | J14: =+F14+I14 -> 50.531986 | K14: 0.3 | L14: =+J14*K14+J14 -> 65.691582 | M14: 100
B15: antonella | C15: 10 | D15: 44 | E15: black 2 piece knit | F15: 20 | G15: 5690 | H15: 9443 | I15: =+F15/G15*H15 -> 33.191564 | J15: =+F15+I15 -> 53.191564 | K15: 0.3 | L15: =+J15*K15+J15 -> 69.149033 | M15: 95
B16: antonella | C16: 11 | D16: 44 | E16: black 2 piece knit | F16: 20 | G16: 5690 | H16: 9443 | I16: =+F16/G16*H16 -> 33.191564 | J16: =+F16+I16 -> 53.191564 | K16: 0.3 | L16: =+J16*K16+J16 -> 69.149033 | M16: 95
B17: antonella | C17: 12 | D17: 46 | E17: black 2 piece knit | F17: 20 | G17: 5690 | H17: 9443 | I17: =+F17/G17*H17 -> 33.191564 | J17: =+F17+I17 -> 53.191564 | K17: 0.3 | L17: =+J17*K17+J17 -> 69.149033 | M17: 95
B18: antonella | C18: 13 | D18: 46 | E18: black 2 piece knit | F18: 20 | G18: 5690 | H18: 9443 | I18: =+F18/G18*H18 -> 33.191564 | J18: =+F18+I18 -> 53.191564 | K18: 0.3 | L18: =+J18*K18+J18 -> 69.149033 | M18: 95 | N18: 60 | P18: nyamakupi | Q18: 45351 | R18: =+N18*10000 -> 600000
E19: JUNE 2020 STOCK | L19: =+J19*K19+J19 -> 0
B20: sincere | C20: 14 | D20: 48 | E20: 2 piece denim dress | F20: 28 | G20: 283 | H20: =+G20+314 -> 597 | I20: =+F20/G20*H20 -> 59.067138 | J20: =+F20+I20 -> 87.067138 | K20: 0.3 | L20: =+J20*K20+J20 -> 113.18728 | M20: 100
E21: december 2020 stock | L21: =+J21*K21+J21 -> 0
B22: pinema | C22: 15 | D22: 42 | E22: white trouser set | F22: 28 | G22: 272 | H22: =+G22+50+16 -> 338 | I22: =+F22/G22*H22 -> 34.794118 | J22: =+F22+I22 -> 62.794118 | K22: 0.3 | L22: =+J22*K22+J22 -> 81.632353 | M22: 110
B23: pinema | C23: 16 | D23: 44 | E23: white trouser set | F23: 28 | G23: 272 | H23: =+G23+50+16 -> 338 | I23: =+F23/G23*H23 -> 34.794118 | J23: =+F23+I23 -> 62.794118 | K23: 0.3 | L23: =+J23*K23+J23 -> 81.632353 | M23: 110
B24: pinema | C24: 17 | D24: 46 | E24: white trouser set | F24: 28 | G24: 272 | H24: =+G24+50+16 -> 338 | I24: =+F24/G24*H24 -> 34.794118 | J24: =+F24+I24 -> 62.794118 | K24: 0.3 | L24: =+J24*K24+J24 -> 81.632353 | M24: 110
B25: pinema | C25: 18 | D25: 48 | E25: white trouser set | F25: 28 | G25: 272 | H25: =+G25+50+16 -> 338 | I25: =+F25/G25*H25 -> 34.794118 | J25: =+F25+I25 -> 62.794118 | K25: 0.3 | L25: =+J25*K25+J25 -> 81.632353 | M25: 110
E26: dec 2021 stock | L26: =+J26*K26+J26 -> 0
A27: ideal | B27: ceber | C27: 19 | D27: 42 | E27: cream dress w gold jacket | F27: 41 | G27: 6556 | H27: 9750 | I27: =+F27/G27*H27 -> 60.97468 | J27: =+F27+I27 -> 101.97468 | K27: 0.3 | L27: =+J27*K27+J27 -> 132.56708 | M27: 150
A28: ideal | B28: ceber | C28: 20 | D28: 44 | E28: cream dress w gold jacket | F28: 41 | G28: 6556 | H28: 9750 | I28: =+F28/G28*H28 -> 60.97468 | J28: =+F28+I28 -> 101.97468 | K28: 0.3 | L28: =+J28*K28+J28 -> 132.56708 | M28: 150
A29: ideal | B29: ceber | C29: 21 | D29: 48 | E29: cream dress w gold jacket | F29: 41 | G29: 6556 | H29: 9750 | I29: =+F29/G29*H29 -> 60.97468 | J29: =+F29+I29 -> 101.97468 | K29: 0.3 | L29: =+J29*K29+J29 -> 132.56708 | M29: 150
A30: ideal | B30: gicca | C30: 22 | D30: 50 | E30: cream dress w gold jacket | F30: 41 | G30: 6556 | H30: 9750 | I30: =+F30/G30*H30 -> 60.97468 | J30: =+F30+I30 -> 101.97468 | K30: 0.3 | L30: =+J30*K30+J30 -> 132.56708 | M30: 150
A31: ideal | B31: gicca | C31: 23 | D31: 54 | E31: cream dress w gold jacket | F31: 41 | G31: 6556 | H31: 9750 | I31: =+F31/G31*H31 -> 60.97468 | J31: =+F31+I31 -> 101.97468 | K31: 0.3 | L31: =+J31*K31+J31 -> 132.56708 | M31: 150
A32: ideal | B32: gicca | C32: 24 | D32: 56 | E32: cream dress w gold jacket | F32: 41 | G32: 6556 | H32: 9750 | I32: =+F32/G32*H32 -> 60.97468 | J32: =+F32+I32 -> 101.97468 | K32: 0.3 | L32: =+J32*K32+J32 -> 132.56708 | M32: 150
E33: NOV Turkey trip
B34: Nesly | C34: 25 | D34: 44 | E34: charcoal stripe skirt suit | F34: 55 | G34: 8267 | H34: 7400 | I34: =+F34/G34*H34 -> 49.231886 | J34: =+F34+I34 -> 104.23189 | K34: 0.3 | L34: =+J34*1.3 -> 135.50145 | M34: 150
B35: Nesly | C35: 26 | D35: 44 | E35: navy skirt suit | F35: 55 | G35: 8267 | H35: 7400 | I35: =+F35/G35*H35 -> 49.231886 | J35: =+F35+I35 -> 104.23189 | K35: 0.3 | L35: =+J35*1.3 -> 135.50145 | M35: 150
B36: Nesly | C36: 27 | D36: 52 | E36: navy skirt suit | F36: 55 | G36: 8267 | H36: 7400 | I36: =+F36/G36*H36 -> 49.231886 | J36: =+F36+I36 -> 104.23189 | K36: 0.3 | L36: =+J36*1.3 -> 135.50145 | M36: 150
B37: murray & co | C37: 28 | D37: 38 | E37: black skirt suit | F37: 60 | G37: 8267 | H37: 7400 | I37: =+F37/G37*H37 -> 53.707512 | J37: =+F37+I37 -> 113.70751 | K37: 0.3 | L37: =+J37*1.3 -> 147.81977 | M37: 80
B38: TEMEL CARGO 29 MAR '23
B39: NESLY | C39: 29 | D39: 40 | E39: black w blue pinstripe | F39: 50 | G39: =+(700+612+375)*1.5 -> 2530.5 | H39: 631 | I39: =+F39/G39*H39 -> 12.467892 | J39: =+F39+I39 -> 62.467892 | K39: 0.4 | L39: =+J39*1.3 -> 81.208259 | M39: 150
B40: NESLY | C40: 30 | E40: black w blue pinstripe | F40: 50 | G40: =+(700+612+375)*1.5 -> 2530.5 | H40: 631 | I40: =+F40/G40*H40 -> 12.467892 | J40: =+F40+I40 -> 62.467892 | K40: 0.4 | L40: =+J40*1.3 -> 81.208259 | M40: 150
...

Sheet layby clients
A1: to | B1: date of purchase | C1: inst dates | D1: name | E1: inv no | F1: invoice total | G1: deposit | H1: inst | J1: layby bal
B3: 45220 | D3: dr zezai | F3: 125 | H3: -50
C4: 45231 | F4: 35 | H4: -75
H5: -10
C6: 45314 | H6: -25
F7: =SUM(F3:F5) -> 160 | H7: =SUM(H3:H6) -> -160 | J7: =+F7+H7 -> 0
B10: 45229 | D10: mrs komichi | F10: =35+35 -> 70 | H10: -25
C11: 45280 | H11: -20
C12: 45330 | H12: -25
F13: =SUM(F10:F11) -> 70 | H13: =SUM(H10:H12) -> -70 | J13: =+F13+H13 -> 0
B16: 45243 | D16: mai nyasha | F16: 55 | H16: -20
C17: 45252 | H17: -15
B18: 45290 | F18: 55 | H18: -20
C19: 45293 | H19: -20
C20: 45293 | H20: -20
C21: 45295 | H21: -15
C22: 45295 | F22: 55 | H22: -15
C23: 45306 | H23: -20
C24: 45313 | H24: -10
C25: 45321 | H25: -10
F26: =SUM(F16:F25) -> 165 | G26: =SUM(G16:G25) -> 0 | H26: =SUM(H16:H25) -> -165 | J26: =+F26+H26 -> 0
B29: 45273 | D29: mai poly | F29: 55 | H29: -25 | L29: 787654076
C30: 45275 | H30: -30
B31: 45278 | F31: 70 | H31: -15
C32: 45313 | H32: -55
F34: =SUM(F29:F31) -> 125 | H34: =SUM(H29:H32) -> -125 | J34: =+F34+H34 -> 0
B37: 45281 | D37: ruth tsopotsa | F37: 420 | H37: -300
D38: returned in stock | H38: -105
H39: -15
F40: =SUM(F37:F39) -> 420 | H40: =SUM(H37:H39) -> -420 | J40: =+F40+H40 -> 0
B43: 45294 | D43: chikwanha | F43: 200 | H43: -80
C44: 45318 | H44: -90
C45: 45338 | H45: -30
F46: =SUM(F43:F44) -> 200 | H46: =SUM(H43:H45) -> -200 | J46: =+F46+H46 -> 0
B49: 45308 | D49: nyadzi | F49: 25 | H49: -10
C50: 45322 | H50: -10
F51: =SUM(F49:F50) -> 25 | H51: =SUM(H49:H50) -> -20 | J51: =+F51+H51 -> 5
B53: 45309 | D53: mrs mhonda | F53: 150 | H53: -25
C54: 22 ap | H54: -125
F55: =SUM(F53:F54) -> 150 | H55: =SUM(H53:H54) -> -150 | J55: =+F55+H55 -> 0
...

Sheet credit clients 
A1: to | C1: date of purchase | D1: inv no. | E1: amount | F1: paid to date | I1: USD Bal 2022
B3: Winnie | E3: 215
A4: 2 | B4: Nyasha Mashingaidz
A5: 7 | B5: majasi | C5: 43088 | E5: =150+60+150+65 -> 425 | F5: =+E5-#REF! -> #REF! | G5: =+F5 -> #REF!
B7: mai chitindi | C7: 43571 | E7: 125
C8: 43597
E9: =SUM(E7:E8) -> 125 | I9: =+E9+#REF! -> #REF!
B11: mai jordan | E11: 65 | F11: -30
C12: 43550 | E12: 65 | F12: -40
C13: 43612 | F13: -50
C14: 43613 | E14: 200
C15: 43847 | F15: -50
E16: =SUM(E11:E15) -> 330 | F16: =SUM(F11:F15) -> -170 | I16: =+E16+F16 -> 160
B18: pauline gatsi | C18: 43546 | D18: 431 | E18: 200
C19: 43551
C20: 43551 | E20: =125+180 -> 305
E21: 175
C22: 43553
C23: 43593 | E23: 65
C24: 43602 | E24: =45+85 -> 130
C25: 43607 | E25: =70+65 -> 135
C26: 43608 | E26: 65
C27: 43616
C28: 43616 | E28: 415
C29: 43630 | E29: 90
C30: 43664
C31: 43664 | E31: 200
C32: 43679 | E32: 300
C33: 43694
C34: 43694 | E34: 100
C35: 43732 | E35: 215
C36: 43748
C37: 43748 | E37: 125
C38: 44169 | E38: 150
C39: 43820 | E39: 120
C40: 43859
C41: 43861 | E41: 280
C42: 43865 | E42: 75
C43: 43867 | E43: 55
C44: 43874 | E44: 50
...

Sheet daily sales
A1: date | B1: USD SALE | C1: PRICE | D1: item description | E1: DISC/OVER | F1: DEBIT CARD | G1: ecocash/ zipit | H1: layby | J1: layby deposit DEBIT | K1: layby inst/ final pmnt CASH | L1: layby inst/ final pmnt DEBIT | M1: credit sale | N1: credit sale payment CASH | O1: credit sale payment DEBIT | P1: disc | Q1: consignment comm | R1: total cash daily received | S1: total daily sales | T1: total debit received
D2: JANUARY
A5: 44928 | B5: 25 | D5: altin yak maroon tennis sale 37
B6: 20 | D6: layby inst Sarah
B7: =SUM(B5:B6) -> 45
A9: 44929 | B9: 190 | D9: elisa star blue flowery chiffon maxi 42 | E9: -10
B10: 80 | C10: 200 | D10: layby mrs chikwanha elisa star pink flowery maxi 44
B11: =SUM(B9:B10) -> 270 | E11: =SUM(E9:E10) -> -10
A13: 44930 | B13: 35 | D13: miss rose green satin top 50
B14: 35 | D14: miss rose black satin top 50
B15: 70 | D15: modafly black dres w polka dot bottom 46
B16: 40 | D16: lasiea navy skirt w bottom frill sale
B17: 72 | D17: cr inst handina
B18: =SUM(B13:B17) -> 252
A20: 44931 | B20: 15 | D20: layby inst sara
B21: 15 | C21: 55 | D21: layby sara pardussi navy jacket sale 48
D22: moda fly - black dress w flared polka dot bottonm 44 | E22: transfer bank
B23: 50 | D23: kifayette blue top w ruffled neck54 mudirira | E23: -5
B24: 125 | D24: cr inst zanele
B26: =SUM(B20:B25) -> 205 | E26: =SUM(E23:E25) -> -5
A28: 45297 | B28: 180 | D28: ixora mint green chiffon gown 58
B29: 35 | D29: layby inst mrs chibwe | E29: account already deleted
B30: =SUM(B28:B29) -> 215
A32: 45298 | D32: returned in stock ruth tsopotsa - dissa beige/black 44
A34: 45300 | B34: 40 | D34: haza scotch jacket w zip design44
D35: alevva denim / satin maxi dress 52
D36: platin pink dress 44
D37: cr purchase raviro
C38: 45 | D38: scosta light blue shirt 44
C39: 55 | D39: la gazelle black trousers w belt 46
B40: =SUM(B34:B39) -> 40
A42: 45301 | B42: 150 | D42: nude beige max dress 44
B43: 15 | D43: layby instalment ruth tsopotsa
B44: =SUM(B42:B43) -> 165
A46: 45302 | B46: 125 | D46: firmas beige dress 44
B47: 55 | D47: luani orange casual dress w front design sale
B48: =SUM(B46:B47) -> 180
A50: 45303 | B50: 5 | D50: bayker panty black 6
A52: 45306 | B52: 20 | D52: layby inst Sarah
B53: 110 | D53: cr inst lilian
...

Sheet sales analysis
A1: to
C2: INITIAL ESTABLISHMENT | D2: GROWTH | E2: NORMAL | F2: NORMAL | G2: COVID | H2: COVID/EASTGATE | I2: COVID | J2: RECOVERY | K2: NORMAL/ AVONDALE/CAR | L2: CAR/baby shop/ RECOVERY
B3: month | C3: year 1 (sept-dec) 2015 | D3: year 2 ( 2016) | E3: year 3 ( 2017) | F3: year 4 (2018) | G3: year 5 (2019) | H3: year 6 2020 | I3: year 7 2021 | J3: year 8 2022 | K3: year 9 2023 | L3: yr 10 2024
B4: jan | D4: 3811 | E4: 5584 | F4: 8183 | G4: 2814 | H4: 4180 | I4: 1485 | J4: 6068 | K4: 4140 | L4: =+'daily sales'!B139 -> 3230
B5: feb | D5: 4126 | E5: 5317 | F5: 5000 | G5: 2883 | H5: 3413 | I5: 1570 | J5: 5403 | K5: 6376 | L5: =+'daily sales'!B264 -> 3380
B6: mar | D6: 5742 | E6: 6635 | F6: 6500 | G6: 6262 | H6: 6532 | I6: 6010 | J6: 6778 | K6: 8031 | L6: =+'daily sales'!B415 -> 5258
B7: apr | D7: 12651 | E7: 7539 | F7: 7200 | G7: 2162 | H7: 128 | I7: 4066 | J7: 8490 | K7: 11232 | L7: =+'daily sales'!B610 -> 7090
B8: may | D8: 5651 | E8: 6359 | F8: 9000 | G8: 6517 | H8: 3594 | I8: 6722 | J8: 8879 | K8: 10926 | L8: =+'daily sales'!B801 -> 7471
B9: jun | D9: 8161 | E9: 11905 | F9: 10000 | G9: 1498 | H9: 3961 | I9: 7798 | J9: 9362 | K9: 7742 | L9: =+'daily sales'!B1022 -> 8907
B10: jul | D10: 6484 | E10: 6736 | F10: 8000 | G10: 6873 | H10: 5060 | I10: 4364 | J10: 6653 | K10: 9525 | L10: =+'daily sales'!B1164 -> 6286
B11: aug | D11: 8230 | E11: 10761 | F11: 7000 | G11: 5505 | H11: 3150 | I11: 6270 | J11: 8335 | K11: 10015
B12: sept | C12: 6540 | D12: 11580 | E12: 6736 | F12: 12000 | G12: 6114 | H12: 5083 | I12: 8932 | J12: 6658 | K12: 8403
B13: oct | C13: 11157 | D13: 10088 | E13: 18642.6 | F13: 15000 | G13: 6691 | H13: 3875 | I13: 6199 | J13: 9675 | K13: 7623
B14: nov | C14: 6993 | D14: 6191 | E14: 9327 | F14: 10000 | G14: 6841 | H14: 4706 | I14: 7739 | J14: 6915 | K14: 8747
B15: dec | C15: 9405 | D15: 8897 | E15: 8279 | F15: 8000 | G15: 7148 | H15: 6947 | I15: 11255 | J15: 8645 | K15: 13002
B16: total | C16: =SUM(C4:C15) -> 34095 | D16: =SUM(D4:D15) -> 91612 | E16: =SUM(E4:E15) -> 103820.6 | F16: =SUM(F4:F15) -> 105883 | G16: =SUM(G4:G15) -> 61308 | H16: =SUM(H4:H15) -> 50629 | I16: =SUM(I4:I15) -> 72410 | J16: =SUM(J4:J15) -> 91861 | ... L16: =SUM(L4:L15) -> 41622
B18: av monthly | C18: =+C16/4 -> 8523.75 | D18: =+D16/12 -> 7634.3333 | E18: =+E16/12 -> 8651.7167 | F18: =+F16/12 -> 8823.5833 | G18: =+G16/12 -> 5109 | H18: =+H16/12 -> 4219.0833 | I18: =+I16/12 -> 6034.1667 | J18: =+J16/12 -> 7655.0833 | K18: =+K16/12 -> 8813.5 | L18: =+L16/12 -> 3468.5
B20: quarterly analysis
B21: 1st | D21: =+D4+D5+D6 -> 13679 | E21: =+E4+E5+E6 -> 17536 | F21: =+F4+F5+F6 -> 19683 | G21: =+G4+G5+G6 -> 11959 | H21: =+H4+H5+H6 -> 14125 | I21: =+I4+I5+I6 -> 9065 | J21: =+J4+J5+J6 -> 18249 | K21: =+K4+K5+K6 -> 18547 | L21: =+L4+L5+L6 -> 11868
B22: 2nd | D22: =+D7+D8+D9 -> 26463 | E22: =+E7+E8+E9 -> 25803 | F22: =+F7+F8+F9 -> 26200 | G22: =+G7+G8+G9 -> 10177 | H22: =+H7+H8+H9 -> 7683 | I22: =+I7+I8+I9 -> 18586 | J22: =+J7+J8+J9 -> 26731 | K22: =+K7+K8+K9 -> 29900 | L22: =+L7+L8+L9 -> 23468
B23: 3rd | D23: =+D10+D11+D12 -> 26294 | E23: =+E10+E11+E12 -> 24233 | F23: =+F10+F11+F12 -> 27000 | G23: =+G10+G11+G12 -> 18492 | H23: =+H10+H11+H12 -> 13293 | I23: =+I10+I11+I12 -> 19566 | J23: =+J10+J11+J12 -> 21646 | K23: =+K10+K11+K12 -> 27943 | L23: =+L10+L11+L12 -> 6286
B24: 4th | D24: =+D13+D14+D15 -> 25176 | E24: =+E13+E14+E15 -> 36248.6 | F24: =+F13+F14+F15 -> 33000 | G24: =+G13+G14+G15 -> 20680 | H24: =+H13+H14+H15 -> 15528 | I24: =+I13+I14+I15 -> 25193 | J24: =+J13+J14+J15 -> 25235 | K24: =+K13+K14+K15 -> 29372 | L24: =+L13+L14+L15 -> 0
D26: =SUM(D21:D25) -> 91612 | E26: =SUM(E21:E25) -> 103820.6 | F26: =SUM(F21:F25) -> 105883 | G26: =SUM(G21:G25) -> 61308 | H26: =SUM(H21:H25) -> 50629 | I26: =SUM(I21:I25) -> 72410 | J26: =SUM(J21:J25) -> 91861 | K26: =SUM(K21:K25) -> 105762 | L26: =SUM(L21:L25) -> 41622
B28: average quarterly | D28: =+D26/4 -> 22903 | E28: =+E26/4 -> 25955.15 | F28: =+F26/4 -> 26470.75 | G28: =+G26/4 -> 15327 | H28: =+H26/4 -> 12657.25 | I28: =+I26/4 -> 18102.5 | J28: =+J26/4 -> 22965.25 | K28: =+K26/4 -> 26440.5 | L28: =+L26/4 -> 10405.5
C32: end november | D32: jan | E32: feb | F32: march | G32: apr | H32: may | I32: june | J32: july | K32: aug | L32: sept
C33: sales | D33: =3230+1300 -> 4530
C34: suzuki | H34: =6000+1000 -> 7000 | I34: 1650 | J34: 350
C35: travel | E35: 1100 | F35: 6000
C36: roundtable | D36: 70 | E36: 70 | F36: 300 | H36: 1300 | I36: 1700
C37: 1000 round | D37: 1000 | E37: 1000 | F37: 1000 | H37: 1000 | I37: 1000
C38: teamwork | D38: 300 | F38: 300 | G38: 300 | H38: 300 | I38: 300
C39: fsbs | D39: 300 | E39: 80 | H39: 300 | I39: 300
C40: baby shop good will | D40: 1000 | E40: 1000
C41: baby shop original stock pur | D41: 780 | F41: 500 | G41: 600
C42: sharewealth | D42: 1000 | E42: 980 | G42: 480 | H42: 480 | I42: 480
C43: rentals EB | D43: 250 | E43: 250 | F43: 250 | G43: 250 | H43: 250 | I43: 250
C44: rentals collectibles | D44: 260 | E44: 260 | F44: 260 | G44: 260 | H44: 260 | I44: 260
C45: simukai
C46: salary Pau | D46: 175 | E46: 175 | F46: 175 | G46: 175 | H46: 175 | I46: 175
C47: salary tatenda | D47: 175 | E47: 175 | F47: 175 | G47: 175 | H47: 175 | I47: 175
...

Sheet sops
A1: to
B2: all layby & credit sales instalments to be updated on invoice for audit purposes
B3: daily analysis to be completed daily & check all transactions against receipts, invoices, pos & zimra machine
B5: DAILY SALES TO BE RECORDED AND RECONCILED DAILY
B7: REGULAR STOCK SPOT CHECK ESP ON NEW STOCK
B9: stock taken by clients home for fitting | G9: double check labels and quanity when returned
G10: double check labels and quanity when going out
G11: record in the stock out diary when stock leaves the shop
G12: tick and cancell returned stock
G13: record stock taken by client on the daily analysis and cash/credit invoice
G14: end of every week cross check if there is stock that went out which has not been returned
B16: discounts | G16: only given on cash purchases
G17: have a cash discount receipt stating discount amount and signed by the client
G18: max discount discretion is $5
B20: cash received allocation
G21: weekly $100 savings | L21: 100
G22: weekly $ 50 education fund savings | L22: 50
F23: balance to | G23: stock procurement | L23: 0.5
G24: investment | L24: 0.1
G25: home improvement | L25: 0.1
G26: working capital | L26: 0.3
B28: STAFF LEAVE DAYS
C29: PAU # of days | D29: dates | G29: TATENDA # of days | H29: dates | K29: nyadzi # of days | L29: dates
C30: 14 | D30: 45292 | G30: 14 | H30: dec '23 - jan '24 | K30: 7 | L30: feb '24
G31: 3 | H31: 19-21 feb
G32: 5 | H32: 26 feb-1 mar
B35: TOTAL | C35: =SUM(C30:C34) -> 14 | G35: =SUM(G30:G34) -> 22 | K35: =SUM(K30:K34) -> 7

Sheet stock purchase 2023
A1: SHOP | B1: shop | C1: label | D1: qnty | E1: size | F1: Item | G1: purchase price / unit $ | H1: total purchase price | I1: total cost excl stock | J1: Indirect Cost / unit | K1: Total Unit Cost | L1: Multiplier | M1: Rec Price | N1: Actual Price | O1: reduced 4 sale | P1: stock take 4 | R1: date | S1: sales
C2: 45323
B3: white moon | C3: wioma | E3: 44 | F3: brown beige winter dress | G3: 25 | M3: 90 | N3: 90 | Q3: macy tagwirei | R3: 45359 | S3: =+N3*18000 -> 1620000
B4: white moon | C4: wioma | E4: 46 | F4: brown beige winter dress | G4: 25 | M4: 90 | N4: 90 | Q4: layby zezai | R4: 45377 | S4: =+N4*20000 -> 1800000
B5: white moon | C5: wioma | E5: 48 | F5: brown beige winter dress | G5: 25 | M5: 90 | N5: 90 | Q5: cash, | R5: 45369 | S5: =+N5*18000 -> 1620000
B6: white moon | C6: wioma | E6: 50 | F6: brown beige winter dress | G6: 25 | M6: 90 | N6: 90 | Q6: cash mai prudence | R6: 45358 | S6: =+N6*18000 -> 1620000
B7: white moon | C7: wioma | E7: 52 | F7: brown winter dress w beige sleeves | G7: 25 | M7: 90 | N7: 90 | Q7: cash | R7: 45384 | S7: =+N7*35000 -> 3150000
B8: white moon | C8: wioma | E8: 54 | F8: brown winter dress w beige sleeves | G8: 25 | M8: 90 | N8: 90
B9: white moon | C9: wioma | E9: 56 | F9: brown winter dress w beige sleeves | G9: 25 | M9: 90 | N9: 90
B10: white moon | C10: wioma | E10: 58 | F10: brown winter dress w beige sleeves | G10: 25 | M10: 90 | N10: 90
B11: white moon | C11: wioma | E11: 44 | F11: black/white scotch w bottom pleats | G11: 25 | M11: 90 | N11: 90 | Q11: cash | R11: 45372 | S11: =+N11*20000 -> 1800000
B12: white moon | C12: wioma | E12: 46 | F12: black/white scotch w bottom pleats | G12: 25 | M12: 90 | N12: 90 | Q12: macy tagwirei | R12: 45359 | S12: =+N12*18000 -> 1620000
B13: white moon | C13: wioma | E13: 48 | F13: black/white scotch w bottom pleats | G13: 25 | M13: 90 | N13: 90 | Q13: cash | R13: 45378 | S13: =+N13*30000 -> 2700000
B14: white moon | C14: wioma | E14: 50 | F14: black/white scotch w bottom pleats | G14: 25 | M14: 90 | N14: 90 | Q14: cash | R14: 45384 | S14: =+N14*35000 -> 3150000
C15: wioma | E15: 44 | F15: beige / brown w front slit design | N15: 90
C16: wioma | E16: 46 | F16: beige / brown w front slit design | N16: 90
C17: wioma | E17: 48 | F17: beige / brown w front slit design | N17: 90
C18: wioma | E18: 50 | F18: beige / brown w front slit design | N18: 90
G19: =SUM(G3:G14) -> 300 | M19: =SUM(M3:M14) -> 1080
C20: 45352
B21: GOWNS
B22: Tango | C22: calino | E22: 42 | F22: green satin wrap over w sheer sleeves | G22: 45 | H22: 4192 | I22: 3417 | J22: =+I22/H22*G22 -> 36.680582 | K22: =+G22+J22 -> 81.680582 | L22: 1.4 | M22: =+K22*L22 -> 114.35281 | N22: 150
B23: Tango | C23: calino | E23: 44 | F23: green satin wrap over w sheer sleeves | G23: 45 | H23: 4192 | I23: 3417 | J23: =+I23/H23*G23 -> 36.680582 | K23: =+G23+J23 -> 81.680582 | L23: 1.4 | M23: =+K23*L23 -> 114.35281 | N23: 150
B24: Tango | C24: calino | E24: 46 | F24: green satin wrap over w sheer sleeves | G24: 45 | H24: 4192 | I24: 3417 | J24: =+I24/H24*G24 -> 36.680582 | K24: =+G24+J24 -> 81.680582 | L24: 1.4 | M24: =+K24*L24 -> 114.35281 | N24: 150 | Q24: cash emilia | R24: 45386 | S24: =+N24*35000 -> 5250000
B25: Tango | C25: calino | E25: 48 | F25: green satin wrap over w sheer sleeves | G25: 45 | H25: 4192 | I25: 3417 | J25: =+I25/H25*G25 -> 36.680582 | K25: =+G25+J25 -> 81.680582 | L25: 1.4 | M25: =+K25*L25 -> 114.35281 | N25: 150 | Q25: mandidzinga | R25: 45379 | S25: =+N25*30000 -> 4500000
B26: Tango | C26: calino | E26: 36 | F26: gold satin wrap over w sheer sleeves | G26: 45 | H26: 4192 | I26: 3417 | J26: =+I26/H26*G26 -> 36.680582 | K26: =+G26+J26 -> 81.680582 | L26: 1.4 | M26: =+K26*L26 -> 114.35281 | N26: 150
B27: Tango | C27: calino | E27: 38 | F27: gold satin wrap over w sheer sleeves | G27: 45 | H27: 4192 | I27: 3417 | J27: =+I27/H27*G27 -> 36.680582 | K27: =+G27+J27 -> 81.680582 | L27: 1.4 | M27: =+K27*L27 -> 114.35281 | N27: 150
B28: Tango | C28: calino | E28: 40 | F28: gold satin wrap over w sheer sleeves | G28: 45 | H28: 4192 | I28: 3417 | J28: =+I28/H28*G28 -> 36.680582 | K28: =+G28+J28 -> 81.680582 | L28: 1.4 | M28: =+K28*L28 -> 114.35281 | N28: 150
B29: Tango | C29: calino | E29: 42 | F29: gold satin wrap over w sheer sleeves | G29: 45 | H29: 4192 | I29: 3417 | J29: =+I29/H29*G29 -> 36.680582 | K29: =+G29+J29 -> 81.680582 | L29: 1.4 | M29: =+K29*L29 -> 114.35281 | N29: 150 | Q29: cash | R29: 45378 | S29: =+N29*30000 -> 4500000
B30: fervente | C30: fervente | E30: 38 | F30: gold gown | G30: 38 | H30: 4192 | I30: 3417 | J30: =+I30/H30*G30 -> 30.974714 | K30: =+G30+J30 -> 68.974714 | L30: 1.4 | M30: =+K30*L30 -> 96.564599 | N30: 125
B31: fervente | C31: fervente | E31: 40 | F31: gold gown | G31: 38 | H31: 4192 | I31: 3417 | J31: =+I31/H31*G31 -> 30.974714 | K31: =+G31+J31 -> 68.974714 | L31: 1.4 | M31: =+K31*L31 -> 96.564599 | N31: 125
B32: fervente | C32: fervente | E32: 42 | F32: gold gown | G32: 38 | H32: 4192 | I32: 3417 | J32: =+I32/H32*G32 -> 30.974714 | K32: =+G32+J32 -> 68.974714 | L32: 1.4 | M32: =+K32*L32 -> 96.564599 | N32: 125
B33: fervente | C33: fervente | E33: 38 | F33: rose gold gown | G33: 29 | H33: 4192 | I33: 3417 | J33: =+I33/H33*G33 -> 23.638597 | K33: =+G33+J33 -> 52.638597 | L33: 1.4 | M33: =+K33*L33 -> 73.694036 | N33: 125
B34: fervente | C34: fervente | E34: 40 | F34: rose gold gown | G34: 29 | H34: 4192 | I34: 3417 | J34: =+I34/H34*G34 -> 23.638597 | K34: =+G34+J34 -> 52.638597 | L34: 1.4 | M34: =+K34*L34 -> 73.694036 | N34: 125
B35: fervente | C35: fervente | E35: 42 | F35: rose gold gown | G35: 29 | H35: 4192 | I35: 3417 | J35: =+I35/H35*G35 -> 23.638597 | K35: =+G35+J35 -> 52.638597 | L35: 1.4 | M35: =+K35*L35 -> 73.694036 | N35: 125
B36: fiero | C36: ladonatella | E36: 44 | F36: black /white sheer one arm gown | G36: 68 | H36: 4192 | I36: 3417 | J36: =+I36/H36*G36 -> 55.428435 | K36: =+G36+J36 -> 123.42844 | L36: 1.4 | M36: =+K36*L36 -> 172.79981 | N36: 200
B37: fiero | C37: ladonatella | E37: crew | F37: black /white sheer one arm gown | G37: 68 | H37: 4192 | I37: 3417 | J37: =+I37/H37*G37 -> 55.428435 | K37: =+G37+J37 -> 123.42844 | L37: 1.4 | M37: =+K37*L37 -> 172.79981 | N37: 200
B38: fiero | C38: ladonatella | E38: 48 | F38: black /white sheer one arm gown | G38: 68 | H38: 4192 | I38: 3417 | J38: =+I38/H38*G38 -> 55.428435 | K38: =+G38+J38 -> 123.42844 | L38: 1.4 | M38: =+K38*L38 -> 172.79981 | N38: 200 | Q38: cash emilia | R38: 45386 | S38: =+N38*35000 -> 7000000
B39: fiero | C39: fiero | E39: 52 | F39: rose gold gown w front slit & sheer sleeve | G39: 68 | H39: 4192 | I39: 3417 | J39: =+I39/H39*G39 -> 55.428435 | K39: =+G39+J39 -> 123.42844 | L39: 1.4 | M39: =+K39*L39 -> 172.79981 | N39: 200
B40: fiero | C40: fiero | E40: 54 | F40: rose gold gown w front slit & sheer sleeve | G40: 68 | H40: 4192 | I40: 3417 | J40: =+I40/H40*G40 -> 55.428435 | K40: =+G40+J40 -> 123.42844 | L40: 1.4 | M40: =+K40*L40 -> 172.79981 | N40: 200
...

Sheet stock movement
B36: stock type | C36: 2022 opening level | D36: 2022 closing level | E36: amnt sold during the year | F36: % sale
A38: 1 | B38: face towels | C38: 9 | D38: 2 | E38: =+C38-D38 -> 7 | F38: =+E38/C38*100 -> 77.777778
A39: 2 | B39: panties | C39: 209 | D39: 69 | E39: =+C39-D39 -> 140 | F39: =+E39/C39*100 -> 66.985646
A40: 3 | B40: clutch bags | C40: 72 | D40: 28 | E40: =+C40-D40 -> 44 | F40: =+E40/C40*100 -> 61.111111
A41: 4 | B41: jerseys | C41: 82 | D41: 32 | E41: =+C41-D41 -> 50 | F41: =+E41/C41*100 -> 60.97561
A42: 5 | B42: scarfs | C42: 24 | D42: 10 | E42: =+C42-D42 -> 14 | F42: =+E42/C42*100 -> 58.333333
A43: 6 | B43: dresses | C43: 912 | D43: 381 | E43: =+C43-D43 -> 531 | F43: =+E43/C43*100 -> 58.223684
A44: 7 | B44: coserts | C44: 19 | D44: 8 | E44: =+C44-D44 -> 11 | F44: =+E44/C44*100 -> 57.894737
A45: 8 | B45: handbags | C45: 57 | D45: 25 | E45: =+C45-D45 -> 32 | F45: =+E45/C45*100 -> 56.140351
A46: 9 | B46: jackets | C46: 48 | D46: 22 | E46: =+C46-D46 -> 26 | F46: =+E46/C46*100 -> 54.166667
A47: 10 | B47: pantyhose | C47: 49 | D47: 25 | E47: =+C47-D47 -> 24 | F47: =+E47/C47*100 -> 48.979592
A48: 11 | B48: tops & blouses | C48: 271 | D48: 139 | E48: =+C48-D48 -> 132 | F48: =+E48/C48*100 -> 48.708487
A49: 12 | B49: dress outfits | C49: 64 | D49: 36 | E49: =+C49-D49 -> 28 | F49: =+E49/C49*100 -> 43.75
... A58: 21 | B58: pajamas | C58: 4 | D58: 3 | E58: =+C58-D58 -> 1 | F58: =+E58/C58*100 -> 25
