Workbook

Sheet Budget
A1: to | B1: trip | C1: date - | D1: destination | E1: ticket | F1: visa | G1: currency commission | H1: acc | I1: misc | J1: transport inc airport | K1: food | L1: extra kg | M1: cargo | N1: airport duty | O1: stock | P1: personal | Q1: 2 MONTHS RENTAL | R1: 2 MONTHS SALARIES | S1: TOTAL COST | T1: TOTAL overheads | U1: total recommende sales value | V1: total actual sales value | W1: profit | X1: profit in USD
B3: istanbul | C3: 30 may-10 june 2021 | D3: istanbul | E3: 930 | F3: 230 | H3: 200 | J3: 10 | K3: 50 | M3: =886+1723+1000 -> 3609 | O3: 9148 | P3: 500 | Q3: 400 | R3: 400 | S3: =SUM(E3:R3) -> 15477
B7: istanbul november 2021 trip
B8: 0 | G8: =844*0.04+75 -> 108.76 | H8: =25*6 -> 150 | I8: =3*15+10 -> 55 | J8: 50 | K8: 20 | L8: 250 | M8: 1200 | N8: 360 | O8: 6556 | P8: 0 | Q8: 400 | R8: 600 | S8: =SUM(B8:R8) -> 9749.76
B10: istanbul kapura Dec | I10: =+O10*0.06 -> 210.3 | M10: =70*17+50+20*17+50 -> 1630 | O10: =1992+1048+465 -> 3505 | Q10: 200 | R10: 700 | S10: =SUM(G10:R10) -> 6245.3
B13: istanbul april2022 | E13: 850 | H13: =135+60 -> 195 | I13: 55 | J13: 50 | K13: 20 | L13: =4*110+75*3 -> 665 | M13: =80*17.5+50 -> 1450 | N13: =720+15+40 -> 775 | O13: =+'stock purchase 2026'!#REF! -> #REF! | P13: =100+15+35+20+17+18+15+10+35 -> 265 | Q13: 300 | R13: 375 | S13: =SUM(E13:R13) -> #REF!
B16: istanbulsept 2022 | C16: 10 -22 sept | D16: istanbul | E16: =1220+135 -> 1355 | F16: 220 | G16: =3000*0.05 -> 150 | H16: =40+30*5+80 -> 270 | I16: 50 | J16: 50 | K16: 50 | L16: =3*120+4*75 -> 660 | M16: 0 | N16: =600+30+40 -> 670 | O16: 6911 | P16: =66+10+200+40+50 -> 366 | Q16: 500 | R16: 375 | S16: =SUM(E16:R16) -> 11627 | T16: =+E16+F16+G16+H16+I16+J16+K16+L16+M16+N16+P16+Q16+R16 -> 4716
B17: via Germany | C17: 17-20 sept | D17: germany | E17: 370
B19: ISTANBUL | C19: 19-27 NOV | D19: ISTANBUL | E19: 800 | H19: 250 | I19: 16 | J19: 50 | K19: 50 | L19: 200 | N19: 480 | O19: 4607 | P19: 250 | Q19: 500 | R19: 400 | S19: =SUM(E19:R19) -> 7603 | T19: =+S19-O19 -> 2996 | U19: =+'stock purchase 2026'!#REF! -> #REF! | V19: =+'stock purchase 2026'!#REF! -> #REF! | W19: =+V19-S19 -> #REF!
B23: istanbul March 2023 | C23: 5-12 mar | D23: istanbul | E23: 1235 | H23: 240 | I23: 100 | J23: 50 | K23: 50 | L23: =500+225 -> 725 | N23: 840 | O23: 8267 | P23: 50 | Q23: =+(2200+500) -> 2700 | R23: 1000 | S23: =SUM(E23:R23) -> 15257 | T23: =+S23-O23 -> 6990
B24: via Germany | C24: 28 feb-4 march | D24: germany | E24: 100 | H24: 180 | I24: 50 | J24: 40 | K24: 40 | S24: =SUM(E24:R24) -> 410 | T24: =+S24 -> 410
T25: =SUM(T23:T24) -> 7400
B26: istanbul | C26: 7-13 march | D26: istanbul | E26: 951 | H26: 240 | I26: 100 | J26: =50+30 -> 80 | K26: =50+20 -> 70 | L26: =500+75*9 -> 1175 | N26: =8*120+90 -> 1050 | O26: 9682 | P26: 400 | Q26: =2200+500 -> 2700 | R26: =+(400+400+200) -> 1000 | S26: =SUM(E26:R26) -> 17448 | T26: =+S26-O26 -> 7766
L28: =+E26+H26+I26+J26+K26+L26+N26 -> 3666 | M28: =+L26+N26 -> 2225 | N28: =32*8 -> 256
L29: =+L28/N28 -> 14.320312 | N29: =+M28/N28 -> 8.6914062
B30: ISTANBUL MAY 2023
B34: ISTANBUL | C34: 2-9 JULY 2023 | D34: istanbul | E34: 1080 | H34: 200 | I34: 50 | J34: =40+40+5+7 -> 92 | K34: 20 | L34: =130+300 -> 430 | M34: =15*16.5+25 -> 272.5 | N34: 480 | O34: 6066 | P34: 200 | Q34: =950*2+250*2 -> 2400 | R34: =+(175*2+100*2)+240 -> 790 | S34: =SUM(E34:R34) -> 12080.5 | T34: =+S34-O34 -> 6014.5
B37: istanbul sept/oct | C37: 25-29 15-18 | D37: istanbul | E37: 930 | F37: 400 | H37: =8*45 -> 360 | I37: =60+100+35+35 -> 230 | J37: =50+30+40+10 -> 130 | K37: 50 | L37: =2*120+3*75 -> 465 | M37: =502+25*16.5+25*16.5 -> 1327 | N37: =4*120 -> 480 | O37: 6440 | P37: 100 | Q37: =950*2+250*2 -> 2400 | R37: =+(175*2+120*2)+240 -> 830 | S37: =SUM(E37:R37) -> 14142 | T37: =+S37-O37 -> 7702
B38: new york | C38: 30-14 oct | D38: new york/ florida | E38: 900 | F38: 160 | H38: =593+180 -> 773 | J38: =42+42+27+60+17+14+8 -> 210 | K38: 180 | L38: =30+40 -> 70 | N38: 120 | O38: 1327 | P38: =54+25+35+29+20+53 -> 216 | S38: =SUM(E38:R38) -> 3956 | T38: =+S38-O38 -> 2629
B39: total | E39: =SUM(E37:E38) -> 1830 | F39: =SUM(F37:F38) -> 560 | G39: =SUM(G37:G38) -> 0 | H39: =SUM(H37:H38) -> 1133 | I39: =SUM(I37:I38) -> 230 | J39: =SUM(J37:J38) -> 340 | K39: =SUM(K37:K38) -> 230 | L39: =SUM(L37:L38) -> 535 | ... P39: =SUM(P37:P38) -> 316 | S39: =SUM(S37:S38) -> 18098 | T39: =SUM(T37:T38) -> 10331
B41: BABY WEAR | C41: 25-29 15-18 | D41: istanbul | E41: 300 | F41: 50 | G41: 0 | H41: 0 | I41: 100 | J41: 20 | K41: 20 | L41: 200 | M41: 439 | N41: 120 | O41: 2400 | Q41: 500 | R41: 300 | S41: =SUM(E41:R41) -> 4449 | T41: =+S41-O41 -> 2049
B44: istanbul | C44: 13-20nov | D44: istanbul | E44: 800 | H44: =6*45 -> 270 | I44: 50 | J44: 30 | K44: 50 | M44: 902 | O44: 3687 | P44: 30 | Q44: 500 | R44: =350+240+360 -> 950 | S44: =SUM(E44:R44) -> 7269 | T44: =+S44-O44 -> 3582
B45: BABY WEAR | E45: 300 | H45: =2*35 -> 70 | I45: 150 | K45: 20 | M45: =568-8*15.5+600 -> 1044 | O45: 1215 | P45: 20 | Q45: 500 | R45: 420 | S45: =SUM(E45:R45) -> 3739 | T45: =+S45-O45 -> 2524
B47: baby wear omer | C47: cargo | M47: 400 | O47: 532 | Q47: 500 | R47: 400 | S47: =SUM(E47:R47) -> 1832 | T47: =+S47-O47 -> 1300
B50: turkey trip august | C50: AUGUST 2024. | E50: 1100 | H50: =45*6 -> 270 | I50: 100 | K50: 50 | M50: 1234 | O50: 5000 | P50: 200 | Q50: =250*2 -> 500 | R50: 800 | S50: =SUM(E50:R50) -> 9254 | T50: =+S50-O50 -> 4254
B51: exotic blossom | E51: 200 | M51: =320+243 -> 563 | O51: 1400 | S51: =SUM(E51:R51) -> 2163 | T51: =+S51-O51 -> 763
B52: baby
B55: CHINA TRIP | C55: 3-12 JAN 2025. | D55: GUANGZHOU | E55: 1100 | H55: =46*5 -> 230 | I55: 50 | J55: 50 | K55: 70 | L55: 83.571429 | M55: =188*18 -> 3384 | N55: 585.15625 | P55: 100
B56: exotic blossom | E56: 800 | F56: 70 | H56: =+H55*0.7 -> 161 | I56: 50 | J56: =+J55*0.7 -> 35 | K56: =+K55*0.7 -> 49 | L56: 84 | M56: 2384 | N56: 585 | O56: 3550 | P56: 100 | Q56: 500 | R56: 800 | S56: =SUM(E56:R56) -> 9168 | T56: =+S56-O56 -> 5618
B57: exotic babies | E57: 300 | F57: 30 | H57: =+H55*0.3 -> 69 | J57: =+J55*0.3 -> 15 | K57: =+K55*0.3 -> 21 | M57: 1000 | O57: 1650 | Q57: 550 | R57: 350 | S57: =SUM(E57:R57) -> 3985 | T57: =+S57-O57 -> 2335
B59: Turkey trip | C59: 26 april - 5 may | D59: istanbul | E59: 1200 | F59: 360 | H59: 280 | I59: 100 | K59: 100 | M59: 2217 | N59: =295.3125+120 -> 415.3125 | O59: 4112 | P59: 100 | Q59: 500 | R59: 560 | S59: =SUM(E59:R59) -> 9944.3125 | T59: =+S59-O59 -> 5832.3125
B61: Turkey trip | C61: 28 SEPT - 5 OCT | D61: ISTANBUL | E61: 1080 | H61: 240 | I61: 75 | K61: 80 | L61: =200+75*4 -> 500 | N61: =400+4000/32 -> 525 | O61: 5225 | P61: 200 | Q61: 500 | R61: 500 | S61: =SUM(E61:R61) -> 8925 | T61: =+S61-O61 -> 3700
T62: =+S62-O62 -> 0
B63: CHINA TRIP | C63: 12-22 NOV | D63: GUANGZHOU | E63: 1425 | F63: 125 | H63: =(588/3*9)/7 -> 252 | I63: 50 | J63: 50 | K63: 80 | L63: 571.42857 | N63: 400 | O63: 4072 | P63: 120 | Q63: 500 | R63: 400 | S63: =SUM(E63:R63) -> 8045.4286 | T63: =+S63-O63 -> 3973.4286
D66: 2026…
C67: 11-18 JAN 2026.. | D67: ISTANBUL | E67: 1050 | H67: 200 | J67: 50 | K67: 50 | L67: 75 | M67: =53*17+125 -> 1026 | N67: 200 | O67: 4609 | P67: 50 | Q67: 500 | R67: 400 | S67: =SUM(E67:R67) -> 8210 | T67: =+S67-O67 -> 3601
B83: NOTES
B84: MARCH TRIP - | C84: FIND MANY CLEARANCE SALES, good opportunity for big margins
C85: buy outfits & dresses for occassions then
C86: buy winter items and leave for may, can also do kapura
...

Sheet STOCK TAKE
A1: to
B2: STOCK TAKE OCTOBER 2020
B4: LABEL | C4: DESCRIPTION | D4: PURCHASE PRICE | E4: SALE PRICE | J4: LABEL | K4: DESCRIPTION | L4: PURCHASE PRICE | M4: SALE PRICE
B6: MISSING STOCK | J6: MISSING STOCK
A7: 1 | B7: Le mirage | C7: burnt orage/white 2 piece | D7: 25 | I7: 1 | J7: adalyn | K7: navy dress w pleated back
A8: 2 | B8: le mirage | C8: navy 2 pc w printed skirt | D8: 25 | J8: versace | K8: grey 2 piece track suit from avondale
A9: 3 | B9: ell shirt dress | C9: shirt dress | D9: 9 | J9: nesly | K9: coffee suit
B10: tights | C10: tights | D10: 5 | K10: nesly coffee suit
B11: oreya | C11: maroon sude wedge shoe | D11: 8 | J11: TANGO EZGI | K11: PINK TOP/FLOWERY SKIRT
D12: =SUM(D7:D11) -> 72
B13: eastgate sales
A14: 1 | B14: yuxi fashion | C14: red wrap over dress | D14: 10 | E14: 45
C15: green dress cotton multi colour
B17: SALES ANALYSIS BY CATGORY
B18: STOCK | C18: OPENING QNTY | D18: CLOSING QNTY | E18: SALES QNTY | F18: % SALE | K18: stock not on stock sheet
B19: DRESS OUTFITS | J19: 1 | K19: mardi | L19: green/beige floral flared dress repeat - | M19: 28 | N19: 110
B20: 2 PIECE OUTFITS
B21: DRESSES | C21: 669 | D21: 355 | E21: =+C21-D21 -> 314 | F21: =+E21/C21*100 -> 46.935725 | K21: oreya white t shirt w front glitter
B22: SKIRTS | C22: 106 | D22: 83 | E22: =+C22-D22 -> 23 | F22: =+E22/C22*100 -> 21.698113 | K22: FI & BI | L22: black jeggin 46 | M22: sold but not on stocksheet
B23: TOPS | C23: 155 | D23: 86 | E23: =+C23-D23 -> 69 | F23: =+E23/C23*100 -> 44.516129
B24: TROUSERS | C24: 59 | D24: 34 | E24: =+C24-D24 -> 25 | F24: =+E24/C24*100 -> 42.372881
B25: WOOLEN TOPS | C25: 99 | D25: 41 | E25: =+C25-D25 -> 58 | F25: =+E25/C25*100 -> 58.585859
B26: JACKETS | C26: 31 | D26: 22 | E26: =+C26-D26 -> 9 | F26: =+E26/C26*100 -> 29.032258
B27: JERSEY | C27: 59 | D27: 26 | E27: =+C27-D27 -> 33 | F27: =+E27/C27*100 -> 55.932203
B28: TRACK SUITS | C28: 59 | D28: 34 | E28: =+C28-D28 -> 25 | F28: =+E28/C28*100 -> 42.372881
B29: SHOES | C29: 200 | D29: 111 | E29: =+C29-D29 -> 89 | F29: =+E29/C29*100 -> 44.5
B30: CLUTCH | C30: 12 | D30: 6 | E30: =+C30-D30 -> 6 | F30: =+E30/C30*100 -> 50
B31: COSERT | C31: 10 | D31: 4 | E31: =+C31-D31 -> 6 | F31: =+E31/C31*100 -> 60
B32: HANDBAGS | C32: 25 | D32: 9 | E32: =+C32-D32 -> 16 | F32: =+E32/C32*100 -> 64
B33: PANTY | C33: 103 | D33: 49 | E33: =+C33-D33 -> 54 | F33: =+E33/C33*100 -> 52.427184
B34: GYPSY SOCKS | C34: 40 | D34: 36 | E34: =+C34-D34 -> 4 | F34: =+E34/C34*100 -> 10
B45: OCTOBER STOCK TAKE 2022
C46: over | D46: under
B47: OVERS
B48: rouge grey knit dress 2 pc w hood
B50: UNDER
A51: channel | B51: navy | E51: balance with the one addedback jan 2022 stock take
B52: SKIRTS
A53: escarell | B53: black knit | E53: To check amount actually bought
A54: escarell | B54: black knit | E54: To check amount actually bought
...

Sheet cashflow
A1: to | B1: CASHFLOW -2018 | C1: Jan | D1: Feb | E1: Mar | F1: Apr | G1: May | H1: Jun | I1: Jul | J1: Aug | K1: Sep | L1: Oct | M1: Nov | N1: Dec | P1: %
B2: INFLOWS
B3: SALES
B4: Cash sales | C4: =+'daily sales'!#REF! -> #REF!
B5: pos purchases
C6: =SUM(C4:C5) -> #REF!
B8: LOANS
B9: stanbic bank loan
B10: loans personal
B11: loans other
B14: refunds
B17: Total | C17: =+C6+C12+C14 -> #REF!
B19: MONTHLY EXPENSES
B20: stock purchases | C20: =+cashbook!#REF!+cashbook!#REF!+cashbook!#REF!+cashbook!#REF!+cashbook!#REF! -> #REF! | S20: 145
B22: operating expenses | C22: =SUM(C23:C58) -> 1903 | S22: 255
B23: parking | C23: 10 | S23: 75
B24: fuel | C24: 20 | S24: 50
B25: salaries
B26: Pauline | S26: 155
B27: Tatenda | S27: 323
B28: allowance self | C28: 321 | S28: 195
B29: staff transport allowance | S29: 62
B30: Pauline | C30: =87+18 -> 105
B31: Tatenda
B32: staff commission
B33: Pauline | C33: 21
B34: Tatenda | C34: 21
B35: rentals | C35: 250 | S35: 30
B36: rates | S36: =SUM(S20:S35) -> 1290
B37: electricity
B38: cleaning & packaging materials & shop utilities | C38: 10
B39: stationery
B40: car running expenses | R40: =346-24-13 -> 309
B41: miscellaneous
B42: airtime | C42: 50
B43: Business refreshments
B44: small asset procurement
B45: big asset procurement | C45: 600
B46: sales discount
B47: refunds
...

Sheet cash budget

Sheet cashbook
A1: to | C1: cash USD | D1: debit card | E1: Cash bond ecocash | F1: cash /DEBIT convert to USD | G1: TOTAL | J1: expenditure | K1: cash | L1: personal
J2: JANUARY 2026..
J3: rentals & opc
J4: city of harare licence 2026 | K4: =+(6044+60+91+4200+63)/25 -> 418.32
J8: salaries & transport
J9: Transport Pau | K9: 80
J10: Transport Tatenda | K10: 80
J11: packaging plastics | K11: 20
J12: travel
J13: accomodation momento | K13: 200
J14: transport | K14: 50
J15: food | K15: 50
J16: misc | K16: 50
J17: stock | M17: =1129/52 -> 21.711538
J18: turkey stock pur | K18: 4609
J19: stock procurement cost
J20: TD freight & duty - angel sandals | K20: 232
J21: turkey stock stock freight & duty | K21: 200
J22: turkey stock 2 freight & AWB | K22: =52.2*7+125 -> 490.4
J23: turkey stock 2 duty | K23: =(14600/33)+120+76 -> 638.42424
J24: stock distribution cost
J25: cleaning & refreshment
J26: packaging plastics | K26: 20
J27: taxation
J28: zimra quarterly tax | K28: 260
J29: loan repayments
J30: viano loan repayment - paid ruwa local board | K30: 100
J33: personal
J34: part salary | L34: =100+10 -> 110
K35: =SUM(K4:K34) -> 7498.1442 | L35: =SUM(L4:L34) -> 110
J38: FEBRUARY
J39: rentals & opc
J40: LAPF jan rentals and opc | K40: =140+40.625 -> 180.625
J41: lapf opc arrear as feb statement - exotic | K41: 93.939394
J42: lapf opc arrear as feb statement - baby shop | K42: 124.24242
J43: salaries & transport
J44: Jan salary Pau | K44: 200
J45: Jan salary Tatenda | K45: 200
J46: Transport Pau | K46: 80
J47: Transport Tatenda | K47: 80
...

Sheet daily sales
A1: date | B1: USD cash SALE | C1: USD POS SALE | D1: ZIG POS SALE | E1: item description | F1: CASH | G1: POS | H1: layby sale cost | I1: layby inst/ deposit / fnl pyment cash | J1: layby inst/ deposit final pmnt DEBIT | K1: credit sale cost | L1: credit sale payment CASH | M1: credit sale payment DEBIT | N1: DISC
A3: 46024 | E3: LAYBY INST MANYUMWA | J3: 65
E4: china daisy brown/beige 3 pc linen set | G4: 110
E5: china coffee/orange chiffon 2pc dress w fur sleeves | G5: 120
E6: layby Eve Mutsvangwa | I6: 90
E7: elise china 2pc linen trouser set | H7: 110
D8: confirm which one | E8: china red/black maxi w black lining | H8: 125
B9: =+J9 -> 65 | C9: =+G9+I9 -> 320 | G9: =SUM(G3:G8) -> 230 | H9: =SUM(H3:H8) -> 235 | I9: =SUM(I3:I8) -> 90 | J9: =SUM(J3:J8) -> 65 | K9: =SUM(K3:K8) -> 0 | L9: =SUM(L3:L8) -> 0 | M9: =SUM(M3:M8) -> 0 | N9: =SUM(N3:N8) -> 0
A11: 46025 | E11: china black 2pc tracksuit w white line | F11: 100
E12: angel original nude shoe on sale | F12: 25
E13: bayker black panties s4 | F13: 5
B14: =+F14 -> 130 | F14: =SUM(F11:F13) -> 130
A16: 46027 | E16: cr inst mrs muzenda | F16: 75
E17: hairband fascinator | F17: 15
B18: =+F18 -> 90 | F18: =SUM(F16:F17) -> 90
A20: 46028 | E20: layby inst eve mutsvangwa | F20: 145
E21: cr inst nampala | F21: 60
E22: china yellow stripe shirt dress | F22: 65
E23: cr pur lydia shoe shop -round fascinator | K23: 25
E24: china gold belt | G24: 5
B25: =+F25 -> 270 | C25: =+G25 -> 5 | F25: =SUM(F20:F24) -> 270 | G25: =SUM(G20:G24) -> 5 | H25: =SUM(H20:H24) -> 0 | I25: =SUM(I20:I24) -> 0 | J25: =SUM(J20:J24) -> 0 | K25: =SUM(K20:K24) -> 25
A27: 46029 | E27: cr pur mrs musapatika
E28: wioma black/grey winter dress | K28: 55
E29: kakor pink /cream chiffon dress | K29: 60
E30: angel brown sandals 39 | K30: 30
K31: =SUM(K28:K30) -> 145
A33: 46030 | E33: black executive bag | F33: 50
E34: bayker black panty xl | F34: 5
E35: angel maroon block heel 10 | F35: 25
E36: angel black heel w top buckle 10 | F36: 25
E37: angel red heel 40 | F37: 25
E38: cr pur tete nyaradzo
E39: x2 china seamless panties xl | K39: 10
E40: china lace panty 3xl | K40: 5
E41: x2 bayker black panty xxl | K41: 10
E42: x2 bayker colourful panty 2xl | K42: 10
E43: channel maroon track dress on sale | G43: 25
E44: cr inst Wendy | F44: 70
B45: =+F45 -> 200 | C45: =+G45 -> 25 | F45: =SUM(F33:F44) -> 200 | G45: =SUM(G33:G44) -> 25 | H45: =SUM(H33:H44) -> 0 | I45: =SUM(I33:I44) -> 0 | J45: =SUM(J33:J44) -> 0 | K45: =SUM(K33:K44) -> 35 | L45: =SUM(L33:L44) -> 0
A47: 46031 | E47: cr inst zvenyika | G47: 100
...

Sheet dresses
B1: SHOP | C1: LABEL | D1: Q | E1: size | F1: Item | H1: pur price | I1: total purchase price | J1: total cost | K1: Indirect Cost / unit | L1: Total Unit Cost | M1: Multiplier | N1: recommended | O1: Actual Price | P1: SALE | Q1: S/T JAN '25 | R1: s/take jan2026 | S1: status | T1: date
F2: BALL GOWNS
C3: TEMEL CARGO APRIL2021
C4: nivola | D4: 1 | E4: 46 | F4: rose gold gown mermaid design | H4: 59 | I4: 959 | J4: 1284 | K4: =+H4/I4*J4 -> 78.994786 | L4: =+H4+K4 -> 137.99479 | M4: 0.3 | N4: =+L4*M4+L4 -> 179.39322 | O4: 200 | P4: 60
C5: nivola | D5: 2 | E5: 44 | F5: rose gold ball gown mermaid style | H5: 67 | I5: 8183 | J5: 13183 | K5: =+H5/I5*J5 -> 107.93853 | L5: =+H5+K5 -> 174.93853 | M5: 0.3 | N5: =+L5*M5+L5 -> 227.42009 | O5: 250 | P5: 80
C6: 44713
C7: nivola | D7: 3 | E7: 42 | F7: gold lace mermaid gown | H7: 75 | I7: 580 | J7: 200 | K7: =+H7/I7*J7 -> 25.862069 | L7: =+H7+K7 -> 100.86207 | M7: 0.3 | N7: =+L7*M7+L7 -> 131.12069 | O7: 150 | P7: 80
C8: nivola | D8: 4 | E8: 44 | F8: gold lace mermaid gown | H8: 75 | I8: 580 | J8: 200 | K8: =+H8/I8*J8 -> 25.862069 | L8: =+H8+K8 -> 100.86207 | M8: 0.3 | N8: =+L8*M8+L8 -> 131.12069 | O8: 150 | P8: 80
C9: Tiana | D9: 6 | E9: 44 | F9: green sleeveless ball gown | H9: 70 | I9: 580 | J9: 200 | K9: =+H9/I9*J9 -> 24.137931 | L9: =+H9+K9 -> 94.137931 | M9: 0.3 | N9: =+L9*M9+L9 -> 122.37931 | O9: 150
C10: Tiana | D10: 7 | E10: 46 | F10: green sleeveless ball gown | H10: 70 | I10: 580 | J10: 200 | K10: =+H10/I10*J10 -> 24.137931 | L10: =+H10+K10 -> 94.137931 | M10: 0.3 | N10: =+L10*M10+L10 -> 122.37931 | O10: 150
C11: Tiana | D11: 8 | E11: 48 | F11: green sleeveless ball gown | H11: 70 | I11: 580 | J11: 200 | K11: =+H11/I11*J11 -> 24.137931 | L11: =+H11+K11 -> 94.137931 | M11: 0.3 | N11: =+L11*M11+L11 -> 122.37931 | O11: 150
C12: Tiana | D12: 9 | E12: 50 | F12: green sleeveless ball gown | H12: 70 | I12: 580 | J12: 200 | K12: =+H12/I12*J12 -> 24.137931 | L12: =+H12+K12 -> 94.137931 | M12: 0.3 | N12: =+L12*M12+L12 -> 122.37931 | O12: 150
C13: 44743
B14: prosperity Tiana | C14: Tiana | D14: 11 | E14: 48 | F14: burgundy gown | H14: 60 | I14: 952 | J14: =+I14+440 -> 1392 | K14: =+H14/I14*J14 -> 87.731092 | L14: =+H14+K14 -> 147.73109 | M14: 0.3 | N14: =+L14*M14+L14 -> 192.05042 | O14: 200
F15: sept 2022 stock | L15: =+H15+K15 -> 0
B16: tiana | C16: tiana | D16: 12 | E16: 48 | F16: green straight pleated gown | H16: 50 | I16: 6911 | J16: 4716 | K16: =+H16/I16*J16 -> 34.11952 | L16: =+H16+K16 -> 84.11952 | M16: 0.3 | N16: =+L16*M16+L16 -> 109.35538 | O16: 80
B17: tiana | C17: tiana | D17: 13 | E17: 50 | F17: green straight pleated gown | H17: 50 | I17: 6911 | J17: 4716 | K17: =+H17/I17*J17 -> 34.11952 | L17: =+H17+K17 -> 84.11952 | M17: 0.3 | N17: =+L17*M17+L17 -> 109.35538 | O17: 80
B18: tiana | C18: tiana | D18: 14 | E18: 44 | F18: green w short dress inside | H18: 65 | I18: 6911 | J18: 4716 | K18: =+H18/I18*J18 -> 44.355375 | L18: =+H18+K18 -> 109.35538 | M18: 0.3 | N18: =+L18*M18+L18 -> 142.16199 | O18: 80
B19: tiana | C19: tiana | D19: 16 | E19: 48 | F19: green w short dress inside | H19: 65 | I19: 6911 | J19: 4716 | K19: =+H19/I19*J19 -> 44.355375 | L19: =+H19+K19 -> 109.35538 | M19: 0.3 | N19: =+L19*M19+L19 -> 142.16199 | O19: 80
B20: tiana | C20: tiana | D20: 17 | E20: 50 | F20: green w short dress inside | H20: 65 | I20: 6911 | J20: 4716 | K20: =+H20/I20*J20 -> 44.355375 | L20: =+H20+K20 -> 109.35538 | M20: 0.3 | N20: =+L20*M20+L20 -> 142.16199 | O20: 80
B21: nivola | C21: nivola | D21: 18 | E21: 42 | F21: black chiffon gown w ruched bust | H21: 40 | I21: 6911 | J21: 4716 | K21: =+H21/I21*J21 -> 27.295616 | L21: =+H21+K21 -> 67.295616 | M21: 0.3 | N21: =+L21*M21+L21 -> 87.4843 | O21: 150 | S21: grey area
B22: favana | C22: favana | D22: 20 | E22: 56 | F22: lilac gown | H22: 70 | I22: 6911 | J22: 4716 | K22: =+H22/I22*J22 -> 47.767327 | L22: =+H22+K22 -> 117.76733 | M22: 0.3 | N22: =+L22*M22+L22 -> 153.09753 | O22: 180
B23: favana | C23: favana | D23: 21 | E23: 52 | F23: mint green gown | H23: 70 | I23: 6911 | J23: 4716 | K23: =+H23/I23*J23 -> 47.767327 | L23: =+H23+K23 -> 117.76733 | M23: 0.3 | N23: =+L23*M23+L23 -> 153.09753 | O23: 180
B24: favana | C24: favana | D24: 22 | E24: 54 | F24: mint green gown | H24: 70 | I24: 6911 | J24: 4716 | K24: =+H24/I24*J24 -> 47.767327 | L24: =+H24+K24 -> 117.76733 | M24: 0.3 | N24: =+L24*M24+L24 -> 153.09753 | O24: 180
B25: nivola | C25: nivola | D25: 23 | E25: 42 | F25: navy chiffon gown w pleated bust | H25: 50 | I25: 6911 | J25: 4716 | K25: =+H25/I25*J25 -> 34.11952 | L25: =+H25+K25 -> 84.11952 | M25: 0.3 | N25: =+L25*M25+L25 -> 109.35538 | O25: 180 | P25: 125
B26: nivola | C26: nivola | D26: 24 | E26: 44 | F26: navy chiffon gown w pleated bust | H26: 50 | I26: 6911 | J26: 4716 | K26: =+H26/I26*J26 -> 34.11952 | L26: =+H26+K26 -> 84.11952 | M26: 0.3 | N26: =+L26*M26+L26 -> 109.35538 | O26: 180 | P26: 125
B27: nivola | C27: nivola | D27: 25 | E27: 46 | F27: navy chiffon gown w pleated bust | H27: 50 | I27: 6911 | J27: 4716 | K27: =+H27/I27*J27 -> 34.11952 | L27: =+H27+K27 -> 84.11952 | M27: 0.3 | N27: =+L27*M27+L27 -> 109.35538 | O27: 180 | P27: 125 | S27: cash returned mabhiza | T27: 45541
B28: nivola | C28: nivola | D28: 26 | E28: 48 | F28: navy chiffon gown w pleated bust | H28: 50 | I28: 6911 | J28: 4716 | K28: =+H28/I28*J28 -> 34.11952 | L28: =+H28+K28 -> 84.11952 | M28: 0.3 | N28: =+L28*M28+L28 -> 109.35538 | O28: 180 | P28: 125
F29: TURKEY TRIP NOV 2022
C30: Donna Miranda | D30: 27 | E30: 46 | F30: gold fishtail | H30: 55 | I30: 4607 | J30: =7503-I30 -> 2896 | K30: =+H30/I30*J30 -> 34.573475 | L30: =+H30+K30 -> 89.573475 | M30: 0.3 | N30: =+L30*M30+L30 -> 116.44552 | O30: 180 | P30: 125
C31: Donna Miranda | D31: 27 | E31: 48 | F31: gold fishtail | H31: 55 | I31: 4607 | J31: =7503-I31 -> 2896 | K31: =+H31/I31*J31 -> 34.573475 | L31: =+H31+K31 -> 89.573475 | M31: 0.3 | N31: =+L31*M31+L31 -> 116.44552 | O31: 180
C32: 9 Aug 2023 temel cargo
C33: nivola | D33: 31 | E33: 44 | F33: nude pleated flared gown | H33: 55 | I33: 440 | J33: =198+20 -> 218 | K33: =+H33/I33*J33 -> 27.25 | L33: =+H33+K33 -> 82.25 | M33: 0.4 | N33: =+L33*1.4 -> 115.15 | O33: 150 | P33: 80
C34: sept. 2023 | F34: GOWNS | I34: 5278
B35: nivola | C35: nivola | D35: 34 | E35: 46 | F35: black stretch gown | H35: 55 | I35: 5278 | J35: 7702 | K35: =+H35/I35*J35 -> 80.259568 | L35: =+H35+K35 -> 135.25957 | M35: 0.4 | N35: =+L35*1.4 -> 189.3634 | O35: 150
B36: nivola | C36: nivola | D36: 35 | E36: 48 | F36: black stretch gown | H36: 55 | I36: 5278 | J36: 7702 | K36: =+H36/I36*J36 -> 80.259568 | L36: =+H36+K36 -> 135.25957 | M36: 0.4 | N36: =+L36*1.4 -> 189.3634 | O36: 150
B37: nivola | C37: nivola | D37: 36 | E37: 50 | F37: black stretch gown | H37: 55 | I37: 5278 | J37: 7702 | K37: =+H37/I37*J37 -> 80.259568 | L37: =+H37+K37 -> 135.25957 | M37: 0.4 | N37: =+L37*1.4 -> 189.3634 | O37: 150
B38: Liza Line | C38: via torino | D38: 38 | E38: 46 | F38: white/ silver ball gown | H38: 65 | I38: 5278 | J38: 7702 | K38: =+H38/I38*J38 -> 94.852217 | L38: =+H38+K38 -> 159.85222 | M38: 0.4 | N38: =+L38*1.4 -> 223.7931 | O38: 180 | P38: 125
C39: 45352
B40: fervente | C40: K | D40: 43 | E40: 42 | F40: gold gown fancy sleeves | H40: 38 | I40: 4192 | J40: 3417 | K40: =+J40/I40*H40 -> 30.974714 | L40: =+H40+K40 -> 68.974714 | M40: 1.4 | N40: =+L40*M40 -> 96.564599 | O40: 125 | P40: 80
...

Sheet jkts & jerserys
B1: SHOP | C1: LABEL | D1: Q | E1: size | F1: Item | G1: pur price | H1: total purchase price | I1: total cost | J1: Indirect Cost / unit | K1: Total Unit Cost | L1: Multiplier | M1: recommended | N1: Actual Price | O1: SALE | P1: S/T JAN '25 | Q1: status | R1: date | S1: sales
F2: JACKETS | M2: =+K2*L2+K2 -> 0
C3: MAY 2019 STOCK | M3: =+K3*L3+K3 -> 0
C4: haza | D4: 5 | E4: 40 | F4: scotch w pocket design | G4: 12 | H4: 8277 | I4: 15182 | J4: =+G4/H4*I4 -> 22.010874 | K4: =+G4+J4 -> 34.010874 | L4: 0.3 | M4: =+K4*L4+K4 -> 44.214136 | N4: 65 | Q4: from avondale
C5: haza | D5: 6 | E5: 46 | F5: scotch w pocket design | G5: 12 | H5: 8277 | I5: 15182 | J5: =+G5/H5*I5 -> 22.010874 | K5: =+G5+J5 -> 34.010874 | L5: 0.3 | M5: =+K5*L5+K5 -> 44.214136 | N5: 65 | Q5: from avondale
C6: gossi/ trieste | D6: 7 | E6: 52 | F6: denim jacket big size | G6: 20 | H6: 787 | I6: =787+388+40+47 -> 1262 | J6: =+G6/H6*I6 -> 32.071156 | K6: =+G6+J6 -> 52.071156 | L6: 0.3 | M6: =+K6*L6+K6 -> 67.692503 | N6: 65
F7: may 2023 stock
B8: white moon | C8: ravir | D8: 10 | E8: 40 | F8: grey/white houndstooth blazer | G8: 25 | H8: 9682 | I8: 7766 | J8: =+G8/H8*I8 -> 20.052675 | K8: =+G8+J8 -> 45.052675 | L8: 0.4 | M8: =+K8*1.4 -> 63.073745 | N8: 100 | Q8: home
B9: white moon | C9: ravir | D9: 11 | E9: 42 | F9: grey/white houndstooth blazer | G9: 25 | H9: 9682 | I9: 7766 | J9: =+G9/H9*I9 -> 20.052675 | K9: =+G9+J9 -> 45.052675 | L9: 0.4 | M9: =+K9*1.4 -> 63.073745 | N9: 100
B10: white moon | C10: ravir | D10: 13 | E10: 38 | F10: blue/white scotch blazer | G10: 25 | H10: 9682 | I10: 7766 | J10: =+G10/H10*I10 -> 20.052675 | K10: =+G10+J10 -> 45.052675 | L10: 0.4 | M10: =+K10*1.4 -> 63.073745 | N10: 100 | Q10: from avondale to home to shop april
B11: white moon | C11: ravir | D11: 14 | E11: 42 | F11: blue/white scotch blazer | G11: 25 | H11: 9682 | I11: 7766 | J11: =+G11/H11*I11 -> 20.052675 | K11: =+G11+J11 -> 45.052675 | L11: 0.4 | M11: =+K11*1.4 -> 63.073745 | N11: 100
B12: roda | C12: roda | D12: 18 | E12: 42 | F12: black short velvet | G12: 35 | H12: 9682 | I12: 7766 | J12: =+G12/H12*I12 -> 28.073745 | K12: =+G12+J12 -> 63.073745 | L12: 0.4 | M12: =+K12*1.4 -> 88.303243 | N12: 125 | Q12: home
B13: roda | C13: roda | D13: 20 | E13: 50 | F13: black short velvet | G13: 35 | H13: 9682 | I13: 7766 | J13: =+G13/H13*I13 -> 28.073745 | K13: =+G13+J13 -> 63.073745 | L13: 0.4 | M13: =+K13*1.4 -> 88.303243 | N13: 125 | Q13: home
C14: may 2025. | F14: roda layby may 2025.
C15: RODA/ SIMODA | E15: 46 | F15: black/beige houndstooth jacket | G15: 23 | H15: 814 | I15: 584 | J15: =+G15/H15*I15 -> 16.501229 | K15: =+G15+J15 -> 39.501229 | M15: =+K15*1.4 -> 55.30172 | N15: 65 | Q15: home
C16: RODA/ SIMODA | E16: 50 | F16: black/beige houndstooth jacket | G16: 23 | H16: 814 | I16: 584 | J16: =+G16/H16*I16 -> 16.501229 | K16: =+G16+J16 -> 39.501229 | M16: =+K16*1.4 -> 55.30172 | N16: 65 | Q16: home
C17: RODA/ SIMODA | E17: 52 | F17: black/beige houndstooth jacket | G17: 23 | H17: 814 | I17: 584 | J17: =+G17/H17*I17 -> 16.501229 | K17: =+G17+J17 -> 39.501229 | M17: =+K17*1.4 -> 55.30172 | N17: 65 | Q17: home cash | R17: 46104
C18: RODA/ SIMODA | E18: 42 | F18: black/beige houndstooth jacket | G18: 23 | H18: 814 | I18: 584 | J18: =+G18/H18*I18 -> 16.501229 | K18: =+G18+J18 -> 39.501229 | M18: =+K18*1.4 -> 55.30172 | N18: 65 | Q18: home
C19: RODA/ SIMODA | E19: 44 | F19: black/beige houndstooth jacket | G19: 23 | H19: 814 | I19: 584 | J19: =+G19/H19*I19 -> 16.501229 | K19: =+G19+J19 -> 39.501229 | M19: =+K19*1.4 -> 55.30172 | N19: 65 | Q19: home
C20: RODA/ SIMODA | E20: 46 | F20: black/beige houndstooth jacket | G20: 23 | H20: 814 | I20: 584 | J20: =+G20/H20*I20 -> 16.501229 | K20: =+G20+J20 -> 39.501229 | M20: =+K20*1.4 -> 55.30172 | N20: 65 | Q20: home
C21: RODA/ SIMODA | E21: 48 | F21: black/beige houndstooth jacket | G21: 23 | H21: 814 | I21: 584 | J21: =+G21/H21*I21 -> 16.501229 | K21: =+G21+J21 -> 39.501229 | M21: =+K21*1.4 -> 55.30172 | N21: 65 | Q21: home
C22: RODA/ SIMODA | E22: 50 | F22: black/beige houndstooth jacket | G22: 23 | H22: 814 | I22: 584 | J22: =+G22/H22*I22 -> 16.501229 | K22: =+G22+J22 -> 39.501229 | M22: =+K22*1.4 -> 55.30172 | N22: 65 | Q22: home - cash | R22: 46119
C23: RODA/ SIMODA | E23: 52 | F23: black/beige houndstooth jacket | G23: 23 | H23: 814 | I23: 584 | J23: =+G23/H23*I23 -> 16.501229 | K23: =+G23+J23 -> 39.501229 | M23: =+K23*1.4 -> 55.30172 | N23: 65 | Q23: home
C24: RODA/ SIMODA | E24: 50 | F24: navy double breast trench coat | G24: 23 | H24: 814 | I24: 584 | J24: =+G24/H24*I24 -> 16.501229 | K24: =+G24+J24 -> 39.501229 | M24: =+K24*1.4 -> 55.30172 | N24: 125 | Q24: home
C25: RODA/ SIMODA | E25: 52 | F25: navy double breast trench coat | G25: 23 | H25: 814 | I25: 584 | J25: =+G25/H25*I25 -> 16.501229 | K25: =+G25+J25 -> 39.501229 | M25: =+K25*1.4 -> 55.30172 | N25: 125 | Q25: home
C26: RODA/ SIMODA | E26: 54 | F26: navy double breast trench coat | G26: 23 | H26: 814 | I26: 584 | J26: =+G26/H26*I26 -> 16.501229 | K26: =+G26+J26 -> 39.501229 | M26: =+K26*1.4 -> 55.30172 | N26: 125 | Q26: home
C27: RODA/ SIMODA | E27: 56 | F27: navy double breast trench coat | G27: 23 | H27: 814 | I27: 584 | J27: =+G27/H27*I27 -> 16.501229 | K27: =+G27+J27 -> 39.501229 | M27: =+K27*1.4 -> 55.30172 | N27: 125 | Q27: home
C28: RODA/ SIMODA | E28: 50 | F28: black double breast trench coat | G28: 23 | H28: 814 | I28: 584 | J28: =+G28/H28*I28 -> 16.501229 | K28: =+G28+J28 -> 39.501229 | M28: =+K28*1.4 -> 55.30172 | N28: 125 | Q28: home
C29: RODA/ SIMODA | E29: 52 | F29: black double breast trench coat | G29: 23 | H29: 814 | I29: 584 | J29: =+G29/H29*I29 -> 16.501229 | K29: =+G29+J29 -> 39.501229 | M29: =+K29*1.4 -> 55.30172 | N29: 125 | Q29: home
C30: RODA/ SIMODA | E30: 54 | F30: black double breast trench coat | G30: 23 | H30: 814 | I30: 584 | J30: =+G30/H30*I30 -> 16.501229 | K30: =+G30+J30 -> 39.501229 | M30: =+K30*1.4 -> 55.30172 | N30: 125 | Q30: home
C31: RODA/ SIMODA | E31: 52 | F31: beige double breast trench coat | G31: 23 | H31: 814 | I31: 584 | J31: =+G31/H31*I31 -> 16.501229 | K31: =+G31+J31 -> 39.501229 | M31: =+K31*1.4 -> 55.30172 | N31: 125 | Q31: home
C32: RODA/ SIMODA | E32: 52 | F32: beige double breast trench coat | G32: 23 | H32: 814 | I32: 584 | J32: =+G32/H32*I32 -> 16.501229 | K32: =+G32+J32 -> 39.501229 | M32: =+K32*1.4 -> 55.30172 | N32: 125 | Q32: home
C33: RODA/ SIMODA | E33: 52 | F33: beige/black 3/4 trench coat with hood | G33: 40 | H33: 814 | I33: 584 | J33: =+G33/H33*I33 -> 28.697789 | K33: =+G33+J33 -> 68.697789 | M33: =+K33*1.4 -> 96.176904 | N33: 125 | Q33: home
C34: RODA/ SIMODA | E34: 54 | F34: beige/black 3/4 trench coat with hood | G34: 40 | H34: 814 | I34: 584 | J34: =+G34/H34*I34 -> 28.697789 | K34: =+G34+J34 -> 68.697789 | M34: =+K34*1.4 -> 96.176904 | N34: 125 | Q34: home
C35: RODA/ SIMODA | E35: 56 | F35: beige/black 3/4 trench coat with hood | G35: 40 | H35: 814 | I35: 584 | J35: =+G35/H35*I35 -> 28.697789 | K35: =+G35+J35 -> 68.697789 | M35: =+K35*1.4 -> 96.176904 | N35: 125 | Q35: home
C36: marifel | E36: L | F36: H & M collection coffee reversible thick coat | G36: 35 | H36: 1304 | I36: 580 | J36: =+G36/H36*I36 -> 15.567485 | K36: =+G36+J36 -> 50.567485 | M36: =+K36*1.4 -> 70.794479 | N36: 120 | Q36: home
C37: marifel | E37: XL | F37: H & M collection coffee reversible thick coat | G37: 35 | H37: 1304 | I37: 580 | J37: =+G37/H37*I37 -> 15.567485 | K37: =+G37+J37 -> 50.567485 | M37: =+K37*1.4 -> 70.794479 | N37: 120 | Q37: home
C38: marifel | E38: L | F38: HSM textile burberry navy 3/4 quilted jacket | G38: 25 | H38: 1304 | I38: 580 | J38: =+G38/H38*I38 -> 11.119632 | K38: =+G38+J38 -> 36.119632 | M38: =+K38*1.4 -> 50.567485 | N38: 100 | Q38: home
C39: marifel | E39: XL | F39: HSM textile burberry navy 3/4 quilted jacket | G39: 25 | H39: 1304 | I39: 580 | J39: =+G39/H39*I39 -> 11.119632 | K39: =+G39+J39 -> 36.119632 | M39: =+K39*1.4 -> 50.567485 | N39: 100 | Q39: home
C40: marifel | E40: 2XL | F40: HSM textile burberry navy 3/4 quilted jacket | G40: 25 | H40: 1304 | I40: 580 | J40: =+G40/H40*I40 -> 11.119632 | K40: =+G40+J40 -> 36.119632 | M40: =+K40*1.4 -> 50.567485 | N40: 100 | Q40: home
...

Sheet suits
B1: SHOP | C1: LABEL | D1: Q | E1: size | F1: Item | G1: pur price | H1: total purchase price | I1: total cost | J1: Indirect Cost / unit | K1: Total Unit Cost | L1: Multiplier | M1: recommended | N1: Actual Price | O1: SALE | P1: S/T JAN '25 | Q1: status | R1: date | S1: sales
F3: OUTFITS & SUITS
B4: femeny | C4: jf lefone | D4: 1 | F4: white dress & jacket | G4: 33 | H4: 5920.5 | I4: 13960 | J4: =+G4/H4*I4 -> 77.810996 | K4: =+G4+J4 -> 110.811 | L4: 0.3 | M4: =+K4*L4+K4 -> 144.05429 | N4: 150
C5: dancing queen | D5: 2 | E5: 48 | F5: silver & black 2 piece | G5: 45 | H5: 5920.5 | I5: 13960 | J5: =+G5/H5*I5 -> 106.1059 | K5: =+G5+J5 -> 151.1059 | L5: 0.3 | M5: =+K5*L5+K5 -> 196.43767 | N5: 100 | P5: separate skirt & jacket
C6: hatunga | D6: 3 | E6: 38 | F6: gold 2 piece with front glitter | M6: =+K6*L6+K6 -> 0 | Q6: to pela mapeza
C7: fascino | D7: 4 | E7: 44 | F7: fascino cream/gold 2pc | G7: 55 | H7: 5500 | I7: 11950 | J7: =+G7/H7*I7 -> 119.5 | L7: 0.3 | M7: =+K7*L7+K7 -> 0 | N7: 220
C8: mavellino | D8: 5 | E8: 42 | F8: striped blue dress suit | G8: 55 | H8: 5690 | I8: 9443 | J8: =+G8/H8*I8 -> 91.276801 | K8: =+G8+J8 -> 146.2768 | L8: 0.3 | N8: 180 | Q8: layby mutema - returned | R8: 45612
C9: golden woman | E9: 48 | F9: cream/peachjacket w peach skirt skirt | N9: 80
C10: golden woman | E10: 50 | F10: cream/peachjacket w peach skirt skirt | N10: 80
C11: doganer | E11: 56 | F11: blush pink 3pc wlong pencil skirt | N11: 80
C12: doganer | E12: 58 | F12: blush pink 3pc wlong pencil skirt | N12: 80
C13: march 2019 stock | M13: =+K13*L13+K13 -> 0
C14: hatunga | D14: 6 | E14: 42 | F14: navy/pink 3 piece | G14: 50 | H14: 4794 | I14: 7939 | J14: =+G14/H14*I14 -> 82.801418 | K14: =+G14+J14 -> 132.80142 | L14: 0.3 | M14: =+K14*L14+K14 -> 172.64184 | N14: 200
C15: hatunga | D15: 7 | E15: 44 | F15: navy/pink 3 piece | G15: 50 | H15: 4794 | I15: 7939 | J15: =+G15/H15*I15 -> 82.801418 | K15: =+G15+J15 -> 132.80142 | L15: 0.3 | M15: =+K15*L15+K15 -> 172.64184 | N15: 200 | Q15: cash returned
F16: FEB 2020 STOCK | M16: =+K16*L16+K16 -> 0
B17: NIDA | C17: lavous | D17: 8 | E17: 48 | F17: scotch & yellow 2 piece | G17: 19 | H17: 5690 | I17: 9443 | J17: =+G17/H17*I17 -> 31.531986 | K17: =+G17+J17 -> 50.531986 | L17: 0.3 | M17: =+K17*L17+K17 -> 65.691582 | N17: 80
C18: antonella | D18: 9 | E18: 44 | F18: black 2 piece knit | G18: 20 | H18: 5690 | I18: 9443 | J18: =+G18/H18*I18 -> 33.191564 | K18: =+G18+J18 -> 53.191564 | L18: 0.3 | M18: =+K18*L18+K18 -> 69.149033 | N18: 95 | Q18: cashtook skirt and purple polo neck top remained
C19: antonella | D19: 10 | E19: 44 | F19: black 2 piece knit | G19: 20 | H19: 5690 | I19: 9443 | J19: =+G19/H19*I19 -> 33.191564 | K19: =+G19+J19 -> 53.191564 | L19: 0.3 | M19: =+K19*L19+K19 -> 69.149033 | N19: 95
C20: antonella | D20: 13 | E20: 46 | F20: black 2 piece knit | G20: 20 | H20: 5690 | I20: 9443 | J20: =+G20/H20*I20 -> 33.191564 | K20: =+G20+J20 -> 53.191564 | L20: 0.3 | M20: =+K20*L20+K20 -> 69.149033 | N20: 95 | O20: 60 | Q20: nyamakupi | R20: 45351 | S20: =+O20*10000 -> 600000
F21: JUNE 2020 STOCK | M21: =+K21*L21+K21 -> 0
C22: sincere | D22: 12 | E22: 48 | F22: 2 piece denim dress | G22: 28 | H22: 283 | I22: =+H22+314 -> 597 | J22: =+G22/H22*I22 -> 59.067138 | K22: =+G22+J22 -> 87.067138 | L22: 0.3 | M22: =+K22*L22+K22 -> 113.18728 | N22: 100 | Q22: cash | R22: 45650
F23: december 2020 stock | M23: =+K23*L23+K23 -> 0
C24: pinema | D24: 13 | E24: 42 | F24: white trouser set | G24: 28 | H24: 272 | I24: =+H24+50+16 -> 338 | J24: =+G24/H24*I24 -> 34.794118 | K24: =+G24+J24 -> 62.794118 | L24: 0.3 | M24: =+K24*L24+K24 -> 81.632353 | N24: 110 | O24: 55
C25: pinema | D25: 14 | E25: 44 | F25: white trouser set | G25: 28 | H25: 272 | I25: =+H25+50+16 -> 338 | J25: =+G25/H25*I25 -> 34.794118 | K25: =+G25+J25 -> 62.794118 | L25: 0.3 | M25: =+K25*L25+K25 -> 81.632353 | N25: 110 | O25: 55
C26: pinema | D26: 15 | E26: 46 | F26: white trouser set | G26: 28 | H26: 272 | I26: =+H26+50+16 -> 338 | J26: =+G26/H26*I26 -> 34.794118 | K26: =+G26+J26 -> 62.794118 | L26: 0.3 | M26: =+K26*L26+K26 -> 81.632353 | N26: 110 | O26: 55
C27: pinema | D27: 16 | E27: 48 | F27: white trouser set | G27: 28 | H27: 272 | I27: =+H27+50+16 -> 338 | J27: =+G27/H27*I27 -> 34.794118 | K27: =+G27+J27 -> 62.794118 | L27: 0.3 | M27: =+K27*L27+K27 -> 81.632353 | N27: 110 | O27: 55
F28: dec 2021 stock | M28: =+K28*L28+K28 -> 0
B29: ideal | C29: ceber | D29: 17 | E29: 42 | F29: cream dress w gold jacket | G29: 41 | H29: 6556 | I29: 9750 | J29: =+G29/H29*I29 -> 60.97468 | K29: =+G29+J29 -> 101.97468 | L29: 0.3 | M29: =+K29*L29+K29 -> 132.56708 | N29: 150
B30: ideal | C30: ceber | D30: 18 | E30: 44 | F30: cream dress w gold jacket | G30: 41 | H30: 6556 | I30: 9750 | J30: =+G30/H30*I30 -> 60.97468 | K30: =+G30+J30 -> 101.97468 | L30: 0.3 | M30: =+K30*L30+K30 -> 132.56708 | N30: 150
B31: ideal | C31: ceber | D31: 19 | E31: 48 | F31: cream dress w gold jacket | G31: 41 | H31: 6556 | I31: 9750 | J31: =+G31/H31*I31 -> 60.97468 | K31: =+G31+J31 -> 101.97468 | L31: 0.3 | M31: =+K31*L31+K31 -> 132.56708 | N31: 150
B32: ideal | C32: gicca | D32: 20 | E32: 50 | F32: cream dress w gold jacket | G32: 41 | H32: 6556 | I32: 9750 | J32: =+G32/H32*I32 -> 60.97468 | K32: =+G32+J32 -> 101.97468 | L32: 0.3 | M32: =+K32*L32+K32 -> 132.56708 | N32: 150
B33: ideal | C33: gicca | D33: 21 | E33: 56 | F33: cream dress w gold jacket | G33: 41 | H33: 6556 | I33: 9750 | J33: =+G33/H33*I33 -> 60.97468 | K33: =+G33+J33 -> 101.97468 | L33: 0.3 | M33: =+K33*L33+K33 -> 132.56708 | N33: 150
B34: ideal | C34: gicca | D34: 22 | E34: 58 | F34: cream dress w gold jacket | G34: 41 | H34: 6556 | I34: 9750 | J34: =+G34/H34*I34 -> 60.97468 | K34: =+G34+J34 -> 101.97468 | L34: 0.3 | M34: =+K34*L34+K34 -> 132.56708 | N34: 150
B35: doganer | C35: doganer | E35: 48 | F35: blue dress / long jacket set | N35: 80
F36: NOV Turkey trip
C37: Nesly | D37: 23 | E37: 44 | F37: charcoal stripe skirt suit | G37: 55 | H37: 8267 | I37: 7400 | J37: =+G37/H37*I37 -> 49.231886 | K37: =+G37+J37 -> 104.23189 | L37: 0.3 | M37: =+K37*1.3 -> 135.50145 | N37: 150 | Q37: cash | R37: 45890
C38: Nesly | D38: 24 | E38: 44 | F38: navy skirt suit | G38: 55 | H38: 8267 | I38: 7400 | J38: =+G38/H38*I38 -> 49.231886 | K38: =+G38+J38 -> 104.23189 | L38: 0.3 | M38: =+K38*1.3 -> 135.50145 | N38: 150
C39: murray & co | D39: 26 | E39: 38 | F39: black skirt suit | G39: 60 | H39: 8267 | I39: 7400 | J39: =+G39/H39*I39 -> 53.707512 | K39: =+G39+J39 -> 113.70751 | L39: 0.3 | M39: =+K39*1.3 -> 147.81977 | N39: 80
C40: TEMEL CARGO 29 MAR '23
C41: NESLY | D41: 27 | F41: black w blue pinstripe | G41: 50 | H41: =+(700+612+375)*1.5 -> 2530.5 | I41: 631 | J41: =+G41/H41*I41 -> 12.467892 | K41: =+G41+J41 -> 62.467892 | L41: 0.4 | M41: =+K41*1.3 -> 81.208259 | N41: 150
...

Sheet hats shoes & bags
B1: SHOP | C1: LABEL | D1: Q | E1: size | F1: Item | G1: pur price | H1: total purchase price | I1: total cost | J1: Indirect Cost / unit | K1: Total Unit Cost | L1: Multiplier | M1: recommended | N1: Actual Price | O1: SALE | P1: S/T JAN '25 | Q1: S/T JAN 2026 | R1: status | S1: date
F3: SHOES
B4: STOCK 2018
C5: life stride | D5: 1 | F5: black sandal low heel | G5: 12 | H5: 5650 | I5: 9750 | J5: =+G5/H5*I5 -> 20.707965 | K5: =+G5+J5 -> 32.707965 | L5: 1.3 | M5: =+K5*L5+K5 -> 75.228319 | N5: 65 | R5: taken home
F6: TURKEY SEPT 2019 | M6: =+K6*L6+K6 -> 0
C7: altin yak | D7: 3 | F7: nude block heel with bow on top | G7: 12 | M7: =+K7*L7+K7 -> 0 | N7: 65 | O7: 25
C8: 44044 | M8: =+K8*L8+K8 -> 0
C9: MRP | D9: 5 | E9: 5 | F9: green flat sandals w buckle | G9: 7.5882353 | M9: =+K9*L9+K9 -> 0 | N9: 25
C10: MRP | D10: 6 | E10: 5 | F10: green flat sandals w buckle | G10: 7.5882353 | M10: =+K10*L10+K10 -> 0 | N10: 25
F11: CHINA STOCK MARCH 2021 | M11: =+K11*L11+K11 -> 0
C12: zara | D12: 7 | E12: 40 | F12: nude heel slip on | G12: 8 | H12: 1050 | I12: 2585 | J12: =+G12/H12*I12 -> 19.695238 | K12: =+G12+J12 -> 27.695238 | L12: 0.3 | M12: =+K12*L12+K12 -> 36.00381 | N12: 45 | R12: taken home
C13: zara | D13: 8 | E13: 40 | F13: nude heel slip on | G13: 8 | H13: 1050 | I13: =+H13+1335+200 -> 2585 | J13: =+G13/H13*I13 -> 19.695238 | K13: =+G13+J13 -> 27.695238 | L13: 0.3 | M13: =+K13*L13+K13 -> 36.00381 | N13: 45 | R13: taken home
C14: zara | D14: 9 | E14: 41 | F14: nude heel slip on | G14: 8 | H14: 1050 | I14: =+H14+1335+200 -> 2585 | J14: =+G14/H14*I14 -> 19.695238 | K14: =+G14+J14 -> 27.695238 | L14: 0.3 | M14: =+K14*L14+K14 -> 36.00381 | N14: 45 | R14: taken home
C15: zara | D15: 10 | E15: 40 | F15: orange heel slip on | G15: 8 | H15: 1050 | I15: =+H15+1335+200 -> 2585 | J15: =+G15/H15*I15 -> 19.695238 | K15: =+G15+J15 -> 27.695238 | L15: 0.3 | M15: =+K15*L15+K15 -> 36.00381 | N15: 45 | R15: taken home
C16: zara | D16: 11 | E16: 41 | F16: gold heel strappy sandal | G16: 8 | H16: 1050 | I16: =+H16+1335+200 -> 2585 | J16: =+G16/H16*I16 -> 19.695238 | K16: =+G16+J16 -> 27.695238 | L16: 0.3 | M16: =+K16*L16+K16 -> 36.00381 | N16: 45 | R16: taken home
C17: zara | D17: 12 | E17: 39 | F17: gold heel strappy sandal | G17: 8 | H17: 1050 | I17: =+H17+1335+200 -> 2585 | J17: =+G17/H17*I17 -> 19.695238 | K17: =+G17+J17 -> 27.695238 | L17: 0.3 | M17: =+K17*L17+K17 -> 36.00381 | N17: 45 | R17: taken home
C18: zara | D18: 13 | E18: 39 | F18: pink heel strappy sandal | G18: 8 | H18: 1050 | I18: =+H18+1335+200 -> 2585 | J18: =+G18/H18*I18 -> 19.695238 | K18: =+G18+J18 -> 27.695238 | L18: 0.3 | M18: =+K18*L18+K18 -> 36.00381 | N18: 45 | R18: taken home
C19: zara | D19: 14 | E19: 40 | F19: pink heel strappy sandal | G19: 8 | H19: 1050 | I19: =+H19+1335+200 -> 2585 | J19: =+G19/H19*I19 -> 19.695238 | K19: =+G19+J19 -> 27.695238 | L19: 0.3 | M19: =+K19*L19+K19 -> 36.00381 | N19: 45 | R19: taken home
C20: zara | D20: 15 | E20: 41 | F20: pink heel strappy sandal | G20: 8 | H20: 1050 | I20: =+H20+1335+200 -> 2585 | J20: =+G20/H20*I20 -> 19.695238 | K20: =+G20+J20 -> 27.695238 | L20: 0.3 | M20: =+K20*L20+K20 -> 36.00381 | N20: 45 | R20: taken home
C21: zara | D21: 16 | E21: 37 | F21: white heeled slip on with buckle | G21: 8 | H21: 1050 | I21: =+H21+1335+200 -> 2585 | J21: =+G21/H21*I21 -> 19.695238 | K21: =+G21+J21 -> 27.695238 | L21: 0.3 | M21: =+K21*L21+K21 -> 36.00381 | N21: 45 | R21: taken home mai poly cash
F22: flat sandal | M22: =+K22*L22+K22 -> 0
C23: charles & keith | D23: 17 | E23: 39 | F23: white flat sandal | G23: 7 | H23: 1050 | I23: =+H23+1335+200 -> 2585 | J23: =+G23/H23*I23 -> 17.233333 | K23: =+G23+J23 -> 24.233333 | L23: 0.3 | M23: =+K23*L23+K23 -> 31.503333 | N23: 30 | R23: taken home
C24: LV | D24: 18 | E24: 39 | F24: brown fur flat sandal | G24: 6 | H24: 1050 | I24: =+H24+1335+200 -> 2585 | J24: =+G24/H24*I24 -> 14.771429 | K24: =+G24+J24 -> 20.771429 | L24: 0.3 | M24: =+K24*L24+K24 -> 27.002857 | N24: 25
C25: zara | D25: 20 | E25: 39 | F25: black plaited flat sandal | G25: 6 | H25: 1050 | I25: =+H25+1335+200 -> 2585 | J25: =+G25/H25*I25 -> 14.771429 | K25: =+G25+J25 -> 20.771429 | L25: 0.3 | M25: =+K25*L25+K25 -> 27.002857 | N25: 25 | O25: 15 | R25: gift rev shandu
C26: zara | D26: 21 | E26: 40 | F26: gold plaited flat sandal | G26: 6 | H26: 1050 | I26: =+H26+1335+200 -> 2585 | J26: =+G26/H26*I26 -> 14.771429 | K26: =+G26+J26 -> 20.771429 | L26: 0.3 | M26: =+K26*L26+K26 -> 27.002857 | N26: 25
C27: zara | D27: 22 | E27: 41 | F27: gold plaited flat sandal | G27: 6 | H27: 1050 | I27: =+H27+1335+200 -> 2585 | J27: =+G27/H27*I27 -> 14.771429 | K27: =+G27+J27 -> 20.771429 | L27: 0.3 | M27: =+K27*L27+K27 -> 27.002857 | N27: 25
C28: zara | D28: 23 | E28: 39 | F28: gold plaited flat sandal | G28: 6 | H28: 1050 | I28: =+H28+1335+200 -> 2585 | J28: =+G28/H28*I28 -> 14.771429 | K28: =+G28+J28 -> 20.771429 | L28: 0.3 | M28: =+K28*L28+K28 -> 27.002857 | N28: 25
C29: zara | D29: 24 | E29: 41 | F29: gold plaited flat sandal | G29: 6 | H29: 1050 | I29: =+H29+1335+200 -> 2585 | J29: =+G29/H29*I29 -> 14.771429 | K29: =+G29+J29 -> 20.771429 | L29: 0.3 | M29: =+K29*L29+K29 -> 27.002857 | N29: 25
C30: zara | D30: 25 | E30: 40 | F30: gold plaited flat sandal | G30: 6 | H30: 1050 | I30: =+H30+1335+200 -> 2585 | J30: =+G30/H30*I30 -> 14.771429 | K30: =+G30+J30 -> 20.771429 | L30: 0.3 | M30: =+K30*L30+K30 -> 27.002857 | N30: 25
C31: zara | D31: 26 | E31: 38 | F31: gold plaited flat sandal | G31: 6 | H31: 1050 | I31: =+H31+1335+200 -> 2585 | J31: =+G31/H31*I31 -> 14.771429 | K31: =+G31+J31 -> 20.771429 | L31: 0.3 | M31: =+K31*L31+K31 -> 27.002857 | N31: 25
C32: zara | D32: 27 | E32: 41 | F32: royal blue plaited flat sandal | G32: 6 | H32: 1050 | I32: =+H32+1335+200 -> 2585 | J32: =+G32/H32*I32 -> 14.771429 | K32: =+G32+J32 -> 20.771429 | L32: 0.3 | M32: =+K32*L32+K32 -> 27.002857 | N32: 25
C33: zara | D33: 28 | E33: 39 | F33: royal blue plaited flat sandal | G33: 6 | H33: 1050 | I33: =+H33+1335+200 -> 2585 | J33: =+G33/H33*I33 -> 14.771429 | K33: =+G33+J33 -> 20.771429 | L33: 0.3 | M33: =+K33*L33+K33 -> 27.002857 | N33: 25
C34: zara | D34: 29 | E34: 40 | F34: royal blue plaited flat sandal | G34: 6 | H34: 1050 | I34: =+H34+1335+200 -> 2585 | J34: =+G34/H34*I34 -> 14.771429 | K34: =+G34+J34 -> 20.771429 | L34: 0.3 | M34: =+K34*L34+K34 -> 27.002857 | N34: 25
F35: BOOTS | M35: =+K35*L35+K35 -> 0
C36: ZARA T | D36: 30 | E36: 39 | F36: Black high ankle w side mesh | G36: 12 | H36: 1050 | I36: =+H36+1335+200 -> 2585 | J36: =+G36/H36*I36 -> 29.542857 | K36: =+G36+J36 -> 41.542857 | L36: 0.3 | M36: =+K36*L36+K36 -> 54.005714 | N36: 65 | R36: taken home
C37: zara | D37: 32 | E37: 37 | F37: navy suede ankle boot | G37: 12 | H37: 1050 | I37: =+H37+1335+200 -> 2585 | J37: =+G37/H37*I37 -> 29.542857 | K37: =+G37+J37 -> 41.542857 | L37: 0.3 | M37: =+K37*L37+K37 -> 54.005714 | N37: 55 | R37: taken home
C38: bongo | D38: 3 | F38: black knee high low wedge boot | M38: =+K38*L38+K38 -> 0 | N38: 70 | R38: taken by tatenda
C39: sept 2021 stock | M39: =+K39*L39+K39 -> 0
C40: altin yak | D40: 34 | E40: 36 | F40: black block heel | G40: 13 | H40: 844 | I40: 1496 | J40: =+G40/H40*I40 -> 23.042654 | K40: =+G40+J40 -> 36.042654 | L40: 0.3 | M40: =+K40*L40+K40 -> 46.85545 | N40: 55
C41: altin yak | D41: 35 | E41: 37 | F41: black block heel | G41: 13 | H41: 844 | I41: 1496 | J41: =+G41/H41*I41 -> 23.042654 | K41: =+G41+J41 -> 36.042654 | L41: 0.3 | M41: =+K41*L41+K41 -> 46.85545 | N41: 55
...

Sheet credit clients 
A1: to | C1: date of purchase | D1: inv no. | E1: amount | F1: paid to date | I1: USD Bal 2024
B2: mai chitindi | C2: 43571 | E2: 125
C3: 43597
E4: =SUM(E2:E3) -> 125 | I4: =+E4 -> 125
B6: mai jordan | E6: 65 | F6: -30
C7: 43550 | E7: 65 | F7: -40
C8: 43612 | F8: -50
C9: 43613 | E9: 200
C10: 43847 | F10: -50
E11: =SUM(E6:E10) -> 330 | F11: =SUM(F6:F10) -> -170 | I11: =+E11+F11 -> 160
B13: pauline gatsi | C13: 43546 | D13: 431 | E13: 200
C14: 43551
C15: 43551 | E15: =125+180 -> 305
E16: 175
C17: 43553
C18: 43593 | E18: 65
C19: 43602 | E19: =45+85 -> 130
C20: 43607 | E20: =70+65 -> 135
C21: 43608 | E21: 65
C22: 43616
C23: 43616 | E23: 415
C24: 43630 | E24: 90
C25: 43664
C26: 43664 | E26: 200
C27: 43679 | E27: 300
C28: 43694
C29: 43694 | E29: 100
C30: 43732 | E30: 215
C31: 43748
C32: 43748 | E32: 125
C33: 44169 | E33: 150
C34: 43820 | E34: 120
C35: 43859
C36: 43861 | E36: 280
C37: 43865 | E37: 75
C38: 43867 | E38: 55
C39: 43874 | E39: 50
C40: 43873 | E40: 125
B41: pauline Gatsi | C41: 43904
E42: =SUM(E13:E41) -> 3375 | K42: 745
...

Sheet layby clients
A1: to | B1: date of purchase | C1: inst dates | D1: name | E1: inv no | F1: invoice total | G1: deposit | H1: inst | J1: layby bal
B4: 45742 | D4: zezai | F4: 150 | H4: -100
F6: =SUM(F4:F5) -> 150 | G6: =SUM(G4:G5) -> 0 | H6: =SUM(H4:H5) -> -100 | J6: =+F6+H6 -> 50
B9: 45859 | D9: memory mugake | F9: 45 | H9: -20 | M9: 1302
M10: 1212
F11: =SUM(F9:F10) -> 45 | G11: =SUM(G9:G10) -> 0 | H11: =SUM(H9:H10) -> -20 | J11: =SUM(F11:I11) -> 25 | M11: =+M9-M10 -> 90
B14: 45969 | D14: wendy munjemu | F14: 150 | H14: -80
C15: 46030 | H15: -70
F16: =SUM(F14:F15) -> 150 | G16: =SUM(G14:G15) -> 0 | H16: =SUM(H14:H15) -> -150 | J16: =+F16+H16 -> 0
B18: 45972 | D18: mai poly | F18: 150 | H18: -25
C19: 46043 | H19: -125
F20: =SUM(F18:F19) -> 150 | G20: =SUM(G18:G19) -> 0 | H20: =SUM(H18:H19) -> -150 | J20: =+F20+H20 -> 0
B22: 45973 | D22: mahufe | F22: 125 | H22: -50
C23: 45992 | H23: -40
C24: 45995
C25: 46092 | H25: -100
F26: =SUM(F22:F24) -> 125 | G26: =SUM(G22:G23) -> 0 | H26: =SUM(H22:H25) -> -190 | J26: =+F26+H26 -> -65
B29: 45990 | D29: chamisa | F29: 65 | H29: -20
D31: RETURNED | F31: =SUM(F29:F30) -> 65 | G31: =SUM(G29:G30) -> 0 | H31: =SUM(H29:H30) -> -20 | J31: =SUM(F31:I31) -> 45
B33: 45993 | D33: chidzenga | F33: 70 | H33: -20
C34: 45995 | F34: 5 | H34: -24
C35: 46041 | H35: -26
F36: =SUM(F33:F34) -> 75 | G36: =SUM(G33:G34) -> 0 | H36: =SUM(H33:H35) -> -70 | J36: =SUM(F36:I36) -> 5
B39: 46003 | D39: manyumwa | F39: 125 | H39: -60
C40: 46024 | H40: -65
F41: =SUM(F39:F40) -> 125 | G41: =SUM(G39:G40) -> 0 | H41: =SUM(H39:H40) -> -125 | J41: =SUM(F41:I41) -> 0
B43: 46003 | D43: tsopotsa | F43: 480 | H43: -20 | I43: disc
H44: -140
C45: 46004 | H45: -160
C46: 46010 | H46: -70
F47: =SUM(F43:F46) -> 480 | G47: =SUM(G43:G46) -> 0 | H47: =SUM(H43:H46) -> -390 | J47: =SUM(F47:I47) -> 90
B49: 46003 | D49: irene | F49: 65 | H49: -30
C50: 46039 | H50: -35
F51: =SUM(F49:F50) -> 65 | G51: =SUM(G49:G50) -> 0 | H51: =SUM(H49:H50) -> -65 | J51: =SUM(F51:I51) -> 0
D53: JANUARY 2026..
B55: 46024 | D55: Eve Mutsvangwa | F55: 235 | H55: -90
C56: 46028 | H56: -145
F57: =SUM(F55:F56) -> 235 | G57: =SUM(G55:G56) -> 0 | H57: =SUM(H55:H56) -> -235 | J57: =SUM(F57:I57) -> 0
B58: 46038 | D58: mr banda | F58: 65 | H58: -30
C59: 46046 | H59: -35
...

Sheet sales analysis
A1: to
C2: INITIAL ESTABLISHMENT | D2: GROWTH | E2: NORMAL | F2: NORMAL | G2: COVID | H2: COVID/EASTGATE | I2: COVID | J2: RECOVERY | K2: NORMAL/ AVONDALE/CAR | L2: RECOVERY | M2: normal
K3: avondale/car | L3: CAR/baby shop | M3: ceteris paribus wedding/ uk university
B4: month | C4: year 1 (sept-dec) 2015 | D4: year 2 ( 2016) | E4: year 3 ( 2017) | F4: year 4 (2018) | G4: year 5 (2019) | H4: year 6 2020 | I4: year 7 2021 | J4: year 8 2022 | K4: year 9 2023 | L4: yr 10 2024 | M4: yr 11 2025 | N4: yr 12 2026
B5: jan | D5: 3811 | E5: 5584 | F5: 8183 | G5: 2814 | H5: 4180 | I5: 1485 | J5: 6068 | K5: 4140 | L5: 3230 | M5: 5024 | N5: =+'daily sales'!B195 -> 5642
B6: feb | D6: 4126 | E6: 5317 | F6: 5000 | G6: 2883 | H6: 3413 | I6: 1570 | J6: 5403 | K6: 6376 | L6: 3380 | M6: 5030 | N6: =+'daily sales'!B378 -> 6915
B7: mar | D7: 5742 | E7: 6635 | F7: 6500 | G7: 6262 | H7: 6532 | I7: 6010 | J7: 6778 | K7: 8031 | L7: 5258 | M7: 6741 | N7: =+'daily sales'!B597 -> 9315
B8: apr | D8: 12651 | E8: 7539 | F8: 7200 | G8: 2162 | H8: 128 | I8: 4066 | J8: 8490 | K8: 11232 | L8: 7090 | M8: 7345 | N8: =+'daily sales'!B810 -> 6284
B9: may | D9: 5651 | E9: 6359 | F9: 9000 | G9: 6517 | H9: 3594 | I9: 6722 | J9: 8879 | K9: 10926 | L9: 7471 | M9: 10118
B10: jun | D10: 8161 | E10: 11905 | F10: 10000 | G10: 1498 | H10: 3961 | I10: 7798 | J10: 9362 | K10: 7742 | L10: 8907 | M10: 9778
B11: jul | D11: 6484 | E11: 6736 | F11: 8000 | G11: 6873 | H11: 5060 | I11: 4364 | J11: 6653 | K11: 9525 | L11: 6370 | M11: 6612
B12: aug | D12: 8230 | E12: 10761 | F12: 7000 | G12: 5505 | H12: 3150 | I12: 6270 | J12: 8335 | K12: 10015 | L12: 7479 | M12: 7650
B13: sept | C13: 6540 | D13: 11580 | E13: 6736 | F13: 12000 | G13: 6114 | H13: 5083 | I13: 8932 | J13: 6658 | K13: 8403 | L13: 6808 | M13: 4785
B14: oct | C14: 11157 | D14: 10088 | E14: 18642.6 | F14: 15000 | G14: 6691 | H14: 3875 | I14: 6199 | J14: 9675 | K14: 7623 | L14: 8649 | M14: 9160
B15: nov | C15: 6993 | D15: 6191 | E15: 9327 | F15: 10000 | G15: 6841 | H15: 4706 | I15: 7739 | J15: 6915 | K15: 8747 | L15: 6038 | M15: 5325
B16: dec | C16: 9405 | D16: 8897 | E16: 8279 | F16: 8000 | G16: 7148 | H16: 6947 | I16: 11255 | J16: 8645 | K16: 13002 | L16: 6840 | M16: 10621
B17: total | C17: =SUM(C5:C16) -> 34095 | D17: =SUM(D5:D16) -> 91612 | E17: =SUM(E5:E16) -> 103820.6 | F17: =SUM(F5:F16) -> 105883 | G17: =SUM(G5:G16) -> 61308 | H17: =SUM(H5:H16) -> 50629 | I17: =SUM(I5:I16) -> 72410 | J17: =SUM(J5:J16) -> 91861 | ... N17: =SUM(N5:N16) -> 28156
B19: av monthly | C19: =+C17/4 -> 8523.75 | D19: =+D17/12 -> 7634.3333 | E19: =+E17/12 -> 8651.7167 | F19: =+F17/12 -> 8823.5833 | G19: =+G17/12 -> 5109 | H19: =+H17/12 -> 4219.0833 | I19: =+I17/12 -> 6034.1667 | J19: =+J17/12 -> 7655.0833 | K19: =+K17/12 -> 8813.5 | ... N19: =+N17/12 -> 2346.3333
B21: quarterly analysis
B22: 1st | D22: =+D5+D6+D7 -> 13679 | E22: =+E5+E6+E7 -> 17536 | F22: =+F5+F6+F7 -> 19683 | G22: =+G5+G6+G7 -> 11959 | H22: =+H5+H6+H7 -> 14125 | I22: =+I5+I6+I7 -> 9065 | J22: =+J5+J6+J7 -> 18249 | K22: =+K5+K6+K7 -> 18547 | ... N22: =+N5+N6+N7 -> 21872
B23: 2nd | D23: =+D8+D9+D10 -> 26463 | E23: =+E8+E9+E10 -> 25803 | F23: =+F8+F9+F10 -> 26200 | G23: =+G8+G9+G10 -> 10177 | H23: =+H8+H9+H10 -> 7683 | I23: =+I8+I9+I10 -> 18586 | J23: =+J8+J9+J10 -> 26731 | K23: =+K8+K9+K10 -> 29900 | ... N23: =+N8+N9+N10 -> 6284
B24: 3rd | D24: =+D11+D12+D13 -> 26294 | E24: =+E11+E12+E13 -> 24233 | F24: =+F11+F12+F13 -> 27000 | G24: =+G11+G12+G13 -> 18492 | H24: =+H11+H12+H13 -> 13293 | I24: =+I11+I12+I13 -> 19566 | J24: =+J11+J12+J13 -> 21646 | K24: =+K11+K12+K13 -> 27943 | ... N24: =+N11+N12+N13 -> 0
B25: 4th | D25: =+D14+D15+D16 -> 25176 | E25: =+E14+E15+E16 -> 36248.6 | F25: =+F14+F15+F16 -> 33000 | G25: =+G14+G15+G16 -> 20680 | H25: =+H14+H15+H16 -> 15528 | I25: =+I14+I15+I16 -> 25193 | J25: =+J14+J15+J16 -> 25235 | K25: =+K14+K15+K16 -> 29372 | ... N25: =+N14+N15+N16 -> 0
D27: =SUM(D22:D26) -> 91612 | E27: =SUM(E22:E26) -> 103820.6 | F27: =SUM(F22:F26) -> 105883 | G27: =SUM(G22:G26) -> 61308 | H27: =SUM(H22:H26) -> 50629 | I27: =SUM(I22:I26) -> 72410 | J27: =SUM(J22:J26) -> 91861 | K27: =SUM(K22:K26) -> 105762 | ... N27: =SUM(N22:N26) -> 28156
B29: average quarterly | D29: =+D27/4 -> 22903 | E29: =+E27/4 -> 25955.15 | F29: =+F27/4 -> 26470.75 | G29: =+G27/4 -> 15327 | H29: =+H27/4 -> 12657.25 | I29: =+I27/4 -> 18102.5 | J29: =+J27/4 -> 22965.25 | K29: =+K27/4 -> 26440.5 | ... M29: =+M27/4 -> 22047.25
D33: month | E33: stock purchase outflow 2024 | F33: inflows - 2024 | G33: stock purchase outflow 2025 | H33: inflows - 2025
D34: jan | F34: =+'daily sales'!#REF! -> #REF! | G34: =+'stock purchase 2026'!I1158 -> 3538.2857 | H34: =+'daily sales'!#REF! -> #REF! | P34: =+'daily sales'!#REF! -> #REF!
D35: feb | E35: =+'stock purchase 2026'!I19 -> 300 | F35: =+'daily sales'!#REF! -> #REF! | G35: =+'stock purchase 2026'!I1169 -> 252 | H35: =+'daily sales'!#REF! -> #REF! | P35: =+'daily sales'!#REF! -> #REF!
D36: mar | E36: =+'stock purchase 2026'!I255 -> 4191.88 | F36: =+'daily sales'!#REF! -> #REF! | G36: =+'stock purchase 2026'!I1222 -> 364.8 | H36: =+'daily sales'!#REF! -> #REF!
B37: =+H46-F34-F35-F36-F37 -> #REF! | D37: apr | E37: =+'stock purchase 2026'!I379 -> 4087 | F37: =+'daily sales'!#REF! -> #REF! | G37: =+'stock purchase 2026'!I1248 -> 41 | H37: =+'daily sales'!#REF! -> #REF!
D38: may | F38: =+'daily sales'!#REF! -> #REF! | G38: =+'stock purchase 2026'!I1863 -> 9628.95 | H38: =+'daily sales'!#REF! -> #REF!
D39: jun | E39: =+'stock purchase 2026'!I458 -> 1960 | F39: =+'daily sales'!#REF! -> #REF! | G39: =+'stock purchase 2026'!I1958 -> 2734.75 | H39: =+'daily sales'!#REF! -> #REF!
D40: jul | E40: =+'stock purchase 2026'!I477 -> 683.5 | F40: =+'daily sales'!#REF! -> #REF! | G40: =+'stock purchase 2026'!I2009 -> 1892 | H40: =+'daily sales'!#REF! -> #REF!
D41: aug | E41: =+'stock purchase 2026'!I650 -> 5598.5 | F41: =+'daily sales'!#REF! -> #REF! | G41: =+'stock purchase 2026'!I2045 -> 832 | H41: =+'daily sales'!#REF! -> #REF!
D42: sept | E42: =+'stock purchase 2026'!I691 -> 824 | F42: =+'daily sales'!#REF! -> #REF! | G42: =+'stock purchase 2026'!I2413 -> 5225.2 | H42: =+'daily sales'!#REF! -> #REF!
D43: oct | E43: =+'stock purchase 2026'!I778 -> 4046.8 | F43: =+'daily sales'!#REF! -> #REF! | G43: =+'stock purchase 2026'!I2466 -> 6497.2 | H43: =+'daily sales'!#REF!+'daily sales'!#REF! -> #REF!
D44: nov | E44: =+'stock purchase 2026'!I853 -> 2300 | F44: =+'daily sales'!#REF! -> #REF! | G44: =+'stock purchase 2026'!I2846 -> 4523.2857 | H44: =+M15 -> 5325
D45: dec | E45: =+'stock purchase 2026'!I871 -> 343 | F45: =+'daily sales'!#REF! -> #REF! | G45: =+'stock purchase 2026'!I2875 -> 489.27536 | H45: =+M16 -> 10621
D46: total | E46: =SUM(E34:E45) -> 24334.68 | F46: =SUM(F34:F45) -> #REF! | G46: =SUM(G34:G45) -> 36018.747 | H46: =SUM(H34:H45) -> #REF! | I46: =SUM(I34:I45) -> 0 | J46: =SUM(J34:J45) -> 0 | K46: =SUM(K34:K45) -> 0 | L46: =SUM(L34:L45) -> 0 | ... P46: =SUM(P34:P45) -> #REF!
B47: cargo | E47: =+cashbook!#REF!+cashbook!#REF!+cashbook!#REF!+cashbook!#REF!+cashbook!#REF!+cashbook!#REF!+cashbook!#REF!+cashbook!#REF!+cashbook!#REF!+cashbook!#REF!+cashbook!#REF!+cashbook!#REF!+cashbook!#REF!+cashbook!#REF!+cashbook!#REF!+cashbook!#REF!+cashbook!#REF!+cashbook!#REF!+cashbook!#REF!+cashbook!#REF! -> #REF! | G47: =+cashbook!#REF!+cashbook!#REF!+cashbook!#REF!+cashbook!#REF!+cashbook!#REF!+cashbook!#REF!+cashbook!#REF!+cashbook!#REF!+cashbook!#REF!+cashbook!#REF!+cashbook!#REF!+cashbook!#REF!+cashbook!#REF!+cashbook!#REF!+cashbook!#REF!+cashbook!#REF!+cashbook!#REF!+cashbook!#REF!+cashbook!#REF!+cashbook!#REF!+cashbook!#REF!+cashbook!#REF!+cashbook!#REF!+cashbook!#REF!+cashbook!#REF!+cashbook!#REF!+cashbook!#REF!+cashbook!#REF!+cashbook!#REF!+cashbook!#REF!+cashbook!#REF!+cashbook!#REF!+cashbook!#REF!+cashbook!#REF!+cashbook!#REF!+cashbook!#REF!+cashbook!#REF!+cashbook!#REF!+cashbook!#REF!+cashbook!#REF! -> #REF!
...

Sheet stock purchase 2026
A1: SHOP | B1: shop | C1: label | E1: qnty | F1: size | G1: Item | I1: purchase price / unit $ | J1: total purchase price | K1: total cost excl stock | L1: Indirect Cost / unit | M1: Total Unit Cost | N1: Multiplier | O1: Rec Price | P1: Actual Price | Q1: reduced 4 sale | R1: stock take 4 | T1: date | U1: sales
C2: 45323
B3: white moon | C3: wioma | F3: 44 | G3: brown beige winter dress | I3: 25 | O3: 90 | P3: 90 | S3: macy tagwirei | T3: 45359 | U3: =+P3*18000 -> 1620000
B4: white moon | C4: wioma | F4: 46 | G4: brown beige winter dress | I4: 25 | O4: 90 | P4: 90 | S4: layby zezai | T4: 45377 | U4: =+P4*20000 -> 1800000
B5: white moon | C5: wioma | F5: 48 | G5: brown beige winter dress | I5: 25 | O5: 90 | P5: 90 | S5: cash, | T5: 45369 | U5: =+P5*18000 -> 1620000
B6: white moon | C6: wioma | F6: 50 | G6: brown beige winter dress | I6: 25 | O6: 90 | P6: 90 | S6: cash mai prudence | T6: 45358 | U6: =+P6*18000 -> 1620000
B7: white moon | C7: wioma | F7: 52 | G7: brown winter dress w beige sleeves | I7: 25 | O7: 90 | P7: 90 | S7: cash | T7: 45384 | U7: =+P7*35000 -> 3150000
B8: white moon | C8: wioma | F8: 54 | G8: brown winter dress w beige sleeves | I8: 25 | O8: 90 | P8: 90
B9: white moon | C9: wioma | F9: 56 | G9: brown winter dress w beige sleeves | I9: 25 | O9: 90 | P9: 90
B10: white moon | C10: wioma | F10: 58 | G10: brown winter dress w beige sleeves | I10: 25 | O10: 90 | P10: 90
B11: white moon | C11: wioma | F11: 44 | G11: black/white scotch w bottom pleats | I11: 25 | O11: 90 | P11: 90 | S11: cash | T11: 45372 | U11: =+P11*20000 -> 1800000
B12: white moon | C12: wioma | F12: 46 | G12: black/white scotch w bottom pleats | I12: 25 | O12: 90 | P12: 90 | S12: macy tagwirei | T12: 45359 | U12: =+P12*18000 -> 1620000
B13: white moon | C13: wioma | F13: 48 | G13: black/white scotch w bottom pleats | I13: 25 | O13: 90 | P13: 90 | S13: cash | T13: 45378 | U13: =+P13*30000 -> 2700000
B14: white moon | C14: wioma | F14: 50 | G14: black/white scotch w bottom pleats | I14: 25 | O14: 90 | P14: 90 | S14: cash | T14: 45384 | U14: =+P14*35000 -> 3150000
C15: wioma | F15: 44 | G15: beige / brown w front slit design | P15: 90
C16: wioma | F16: 46 | G16: beige / brown w front slit design | P16: 90
C17: wioma | F17: 48 | G17: beige / brown w front slit design | P17: 90
C18: wioma | F18: 50 | G18: beige / brown w front slit design | P18: 90
G19: FEBRUARY TOTAL | I19: =SUM(I3:I14) -> 300 | O19: =SUM(O3:O14) -> 1080
B21: GOWNS | G21: MARCH .2024
B22: Tango | C22: calino | F22: 42 | G22: green satin wrap over w sheer sleeves | I22: 45 | J22: 4192 | K22: 3417 | L22: =+K22/J22*I22 -> 36.680582 | M22: =+I22+L22 -> 81.680582 | N22: 1.4 | O22: =+M22*N22 -> 114.35281 | P22: 150
B23: Tango | C23: calino | F23: 44 | G23: green satin wrap over w sheer sleeves | I23: 45 | J23: 4192 | K23: 3417 | L23: =+K23/J23*I23 -> 36.680582 | M23: =+I23+L23 -> 81.680582 | N23: 1.4 | O23: =+M23*N23 -> 114.35281 | P23: 150
